Workbook

Sheet Cockpit
A1: =VLOOKUP(LARGE(K$48:K$77, L1),K$48:L$77,2,FALSE) -> Denges | L1: 1
A2: =VLOOKUP(LARGE(K$48:K$77, L2),K$48:L$77,2,FALSE) -> Forel (Lavaux) | L2: 2
A3: =VLOOKUP(LARGE(K$48:K$77, L3),K$48:L$77,2,FALSE) -> Savigny | L3: 3
A4: =VLOOKUP(LARGE(K$48:K$77, L4),K$48:L$77,2,FALSE) -> Belmont-sur-Lausanne | L4: 4
A5: =VLOOKUP(LARGE(K$48:K$77, L5),K$48:L$77,2,FALSE) -> Etagnières | B5: BCV seule solution | C5: BCV seule solution | D5: öv reporting | E5: OFS | F5: Prompt IA | G5: Prompt IA | H5: Site du canton de Vaud | I5: site du canton de Vaud | L5: 5
B6: A | C6: A1 | D6: B | E6: C | F6: D | G6: E | H6: F | I6: G | L6: 6
B7: Prix maisons | C7: Prix appartements | D7: Desserte transports publiques | E7: Offre commerces | F7: Qualité de l'air | G7: Offre de place de divertissements | H7: Coefficient fiscaux communaux | I7: Disponibilité logements | L7: 7
B8: 5 | C8: 5 | D8: 7 | E8: 3 | F8: 4 | G8: 8 | H8: 5 | I8: 5 | L8: 8 | O8: Donnée | P8: Onglet du fichier | Q8: Lien
D9: 1 | L9: 9 | N9: 1 | O9: Les prix de l'immobilier par commune et par district vaudois | P9: A | Q9: https://www.bcv.ch/pointsforts/dans-le-canton/bcv-immobilier/les-prix-de-l-immobilier-par-commune-et-par-district-vaudois2.html
D10: 2 | L10: 10 | N10: 2 | O10: Liste de tous les arrêts TP Suisses par commune | P10: B | Q10: Liste des arrêts (Aujourd'hui) — Fahrplanauskunft öV Schweiz
B11: Appart. Prix bas | C11: Maison prix bas | E11: Nombre approx. d'établissements commerciaux | F11: Indice (IQA) | G11: Total places | H11: Impôt rentrée argent | I11: Total logements vacants | N11: 3 | O11: Commerces Suisses par cantons/ commune | P11: C | Q11: Recherche de la raison de commerce | Index central des raisons de commerce
B12: Appart. Prix haut | C12: Maison prix haut | N12: 4 | O12: Qualité de l'air | P12: D | Q12: https://www.lausanne.ch/portrait/carte-identite/environnement/qualite-de-l-air.html
A13: Score commune | N13: 5 | O13: Proximité parc / places de jeux / lac | P13: E
A14: Assens | B14: =(INDEX(A!A:E,MATCH(Cockpit!$A14,A!A:A,0),MATCH(B$11,INDIRECT(B$6 & "!1:1"),0))+INDEX(INDIRECT(B$6 & "!A:G"),MATCH(Cockpit!$A14,INDIRECT(B$6 & "!A:A"),0),MATCH(B$12,INDIRECT(B$6 & "!1:1"),0)))/2 -> 900000 | C14: =(INDEX(INDIRECT(C$6 & "!A:G"),MATCH(Cockpit!$A14,INDIRECT(C$6 & "!A:A"),0),MATCH(C$11,INDIRECT(C$6 & "!1:1"),0))+INDEX(INDIRECT(C$6 & "!A:G"),MATCH(Cockpit!$A14,INDIRECT(C$6 & "!A:A"),0),MATCH(C$12,INDIRECT(C$6 & "!1:1"),0)))/2 -> 1450000 | D14: =LOG((D$9*COUNTIF(B!F:F,Cockpit!A14)-COUNTIFS(B!F:F,Cockpit!A14,B!D:D,"TRAIN") + COUNTIFS(B!F:F,Cockpit!A14,B!D:D,"TRAIN")*D$10)/L14+1) -> 0.0010389825 | E14: =LOG(INDEX(INDIRECT(E$6 & "!A:G"),MATCH(Cockpit!$A14,INDIRECT(E$6 & "!A:A"),0),MATCH(E$11,INDIRECT(E$6 & "!1:1"),0))/L14+1) -> 0.017832777 | F14: =INDEX(INDIRECT(F$6 & "!A:G"),MATCH(Cockpit!$A14,INDIRECT(F$6 & "!A:A"),0),MATCH(F$11,INDIRECT(F$6 & "!1:1"),0)) -> 25 | G14: =LOG((INDEX(INDIRECT(G$6 & "!A:G"),MATCH(Cockpit!$A14,INDIRECT(G$6 & "!A:A"),0),MATCH(G$11,INDIRECT(G$6 & "!1:1"),0))/L14)+1) -> 0.00051980196 | H14: =INDEX(INDIRECT(H$6 & "!A:G"),MATCH(Cockpit!$A14,INDIRECT(H$6 & "!A:A"),0),MATCH(H$11,INDIRECT(H$6 & "!1:1"),0)) -> 70 | I14: =LOG(INDEX(INDIRECT(I$6 & "!A:G"),MATCH(Cockpit!$A14,INDIRECT(I$6 & "!A:A"),0),MATCH(I$11,INDIRECT(I$6 & "!1:1"),0))/L14+1) -> 0.025256795 | K14: Assens | L14: 1670 | N14: 6 | O14: Accueil extrafamilial et parascolaire | P14: F | Q14: https://www.bfs.admin.ch/bfs/fr/home/actualites/quoi-de-neuf.gnpdetail.2024-0551.html
A15: Belmont-sur-Lausanne | B15: =(INDEX(INDIRECT(B$6 & "!A:G"),MATCH(Cockpit!$A15,INDIRECT(B$6 & "!A:A"),0),MATCH(B$11,INDIRECT(B$6 & "!1:1"),0))+INDEX(INDIRECT(B$6 & "!A:G"),MATCH(Cockpit!$A15,INDIRECT(B$6 & "!A:A"),0),MATCH(B$12,INDIRECT(B$6 & "!1:1"),0)))/2 -> 1250000 | C15: =(INDEX(INDIRECT(C$6 & "!A:G"),MATCH(Cockpit!$A15,INDIRECT(C$6 & "!A:A"),0),MATCH(C$11,INDIRECT(C$6 & "!1:1"),0))+INDEX(INDIRECT(C$6 & "!A:G"),MATCH(Cockpit!$A15,INDIRECT(C$6 & "!A:A"),0),MATCH(C$12,INDIRECT(C$6 & "!1:1"),0)))/2 -> 1750000 | D15: =LOG((D$9*COUNTIF(B!F:F,Cockpit!A15)-COUNTIFS(B!F:F,Cockpit!A15,B!D:D,"TRAIN") + COUNTIFS(B!F:F,Cockpit!A15,B!D:D,"TRAIN")*D$10)/L15+1) -> 0.0028746685 | E15: =LOG(INDEX(INDIRECT(E$6 & "!A:G"),MATCH(Cockpit!$A15,INDIRECT(E$6 & "!A:A"),0),MATCH(E$11,INDIRECT(E$6 & "!1:1"),0))/L15+1) -> 0.026883239 | F15: =INDEX(INDIRECT(F$6 & "!A:G"),MATCH(Cockpit!$A15,INDIRECT(F$6 & "!A:A"),0),MATCH(F$11,INDIRECT(F$6 & "!1:1"),0)) -> 40 | G15: =LOG((INDEX(INDIRECT(G$6 & "!A:G"),MATCH(Cockpit!$A15,INDIRECT(G$6 & "!A:A"),0),MATCH(G$11,INDIRECT(G$6 & "!1:1"),0))/L15)+1) -> 0.00044349708 | H15: =INDEX(INDIRECT(H$6 & "!A:G"),MATCH(Cockpit!$A15,INDIRECT(H$6 & "!A:A"),0),MATCH(H$11,INDIRECT(H$6 & "!1:1"),0)) -> 72 | I15: =LOG(INDEX(INDIRECT(I$6 & "!A:G"),MATCH(Cockpit!$A15,INDIRECT(I$6 & "!A:A"),0),MATCH(I$11,INDIRECT(I$6 & "!1:1"),0))/L15+1) -> 0.00055430063 | K15: Belmont-sur-Lausanne | L15: 3915 | N15: 8 | O15: Coefficient communaux | P15: G | Q15: https://www.vd.ch/etat-droit-finances/communes/finances-communales/arretes-dimposition-et-tableaux-des-impots-communaux
A16: Bourg-en-Lavaux | B16: =(INDEX(INDIRECT(B$6 & "!A:G"),MATCH(Cockpit!$A16,INDIRECT(B$6 & "!A:A"),0),MATCH(B$11,INDIRECT(B$6 & "!1:1"),0))+INDEX(INDIRECT(B$6 & "!A:G"),MATCH(Cockpit!$A16,INDIRECT(B$6 & "!A:A"),0),MATCH(B$12,INDIRECT(B$6 & "!1:1"),0)))/2 -> 1450000 | C16: =(INDEX(INDIRECT(C$6 & "!A:G"),MATCH(Cockpit!$A16,INDIRECT(C$6 & "!A:A"),0),MATCH(C$11,INDIRECT(C$6 & "!1:1"),0))+INDEX(INDIRECT(C$6 & "!A:G"),MATCH(Cockpit!$A16,INDIRECT(C$6 & "!A:A"),0),MATCH(C$12,INDIRECT(C$6 & "!1:1"),0)))/2 -> 2150000 | D16: =LOG((D$9*COUNTIF(B!F:F,Cockpit!A16)-COUNTIFS(B!F:F,Cockpit!A16,B!D:D,"TRAIN") + COUNTIFS(B!F:F,Cockpit!A16,B!D:D,"TRAIN")*D$10)/L16+1) -> 0.0023217937 | E16: =LOG(INDEX(INDIRECT(E$6 & "!A:G"),MATCH(Cockpit!$A16,INDIRECT(E$6 & "!A:A"),0),MATCH(E$11,INDIRECT(E$6 & "!1:1"),0))/L16+1) -> 0.024198764 | F16: =INDEX(INDIRECT(F$6 & "!A:G"),MATCH(Cockpit!$A16,INDIRECT(F$6 & "!A:A"),0),MATCH(F$11,INDIRECT(F$6 & "!1:1"),0)) -> 35 | G16: =LOG((INDEX(INDIRECT(G$6 & "!A:G"),MATCH(Cockpit!$A16,INDIRECT(G$6 & "!A:A"),0),MATCH(G$11,INDIRECT(G$6 & "!1:1"),0))/L16)+1) -> 0.00048139057 | H16: =INDEX(INDIRECT(H$6 & "!A:G"),MATCH(Cockpit!$A16,INDIRECT(H$6 & "!A:A"),0),MATCH(H$11,INDIRECT(H$6 & "!1:1"),0)) -> 62.5 | I16: =LOG(INDEX(INDIRECT(I$6 & "!A:G"),MATCH(Cockpit!$A16,INDIRECT(I$6 & "!A:A"),0),MATCH(I$11,INDIRECT(I$6 & "!1:1"),0))/L16+1) -> 0.00056157048 | K16: Bourg-en-Lavaux | L16: 5410 | N16: 9 | O16: Logements disponibles par communes | P16: H | Q16: Communes_Logvac.xlsx
A17: Bremblens | B17: =(INDEX(INDIRECT(B$6 & "!A:G"),MATCH(Cockpit!$A17,INDIRECT(B$6 & "!A:A"),0),MATCH(B$11,INDIRECT(B$6 & "!1:1"),0))+INDEX(INDIRECT(B$6 & "!A:G"),MATCH(Cockpit!$A17,INDIRECT(B$6 & "!A:A"),0),MATCH(B$12,INDIRECT(B$6 & "!1:1"),0)))/2 -> 1150000 | C17: =(INDEX(INDIRECT(C$6 & "!A:G"),MATCH(Cockpit!$A17,INDIRECT(C$6 & "!A:A"),0),MATCH(C$11,INDIRECT(C$6 & "!1:1"),0))+INDEX(INDIRECT(C$6 & "!A:G"),MATCH(Cockpit!$A17,INDIRECT(C$6 & "!A:A"),0),MATCH(C$12,INDIRECT(C$6 & "!1:1"),0)))/2 -> 1650000 | D17: =LOG((D$9*COUNTIF(B!F:F,Cockpit!A17)-COUNTIFS(B!F:F,Cockpit!A17,B!D:D,"TRAIN") + COUNTIFS(B!F:F,Cockpit!A17,B!D:D,"TRAIN")*D$10)/L17+1) -> 0.00072322162 | E17: =LOG(INDEX(INDIRECT(E$6 & "!A:G"),MATCH(Cockpit!$A17,INDIRECT(E$6 & "!A:A"),0),MATCH(E$11,INDIRECT(E$6 & "!1:1"),0))/L17+1) -> 0.024622475 | F17: =INDEX(INDIRECT(F$6 & "!A:G"),MATCH(Cockpit!$A17,INDIRECT(F$6 & "!A:A"),0),MATCH(F$11,INDIRECT(F$6 & "!1:1"),0)) -> 25 | G17: =LOG((INDEX(INDIRECT(G$6 & "!A:G"),MATCH(Cockpit!$A17,INDIRECT(G$6 & "!A:A"),0),MATCH(G$11,INDIRECT(G$6 & "!1:1"),0))/L17)+1) -> 0.0014452409 | H17: =INDEX(INDIRECT(H$6 & "!A:G"),MATCH(Cockpit!$A17,INDIRECT(H$6 & "!A:A"),0),MATCH(H$11,INDIRECT(H$6 & "!1:1"),0)) -> 68 | I17: =LOG(INDEX(INDIRECT(I$6 & "!A:G"),MATCH(Cockpit!$A17,INDIRECT(I$6 & "!A:A"),0),MATCH(I$11,INDIRECT(I$6 & "!1:1"),0))/L17+1) -> 0.00072322162 | K17: Bremblens | L17: 600
A18: Bussigny | B18: =(INDEX(INDIRECT(B$6 & "!A:G"),MATCH(Cockpit!$A18,INDIRECT(B$6 & "!A:A"),0),MATCH(B$11,INDIRECT(B$6 & "!1:1"),0))+INDEX(INDIRECT(B$6 & "!A:G"),MATCH(Cockpit!$A18,INDIRECT(B$6 & "!A:A"),0),MATCH(B$12,INDIRECT(B$6 & "!1:1"),0)))/2 -> 1250000 | C18: =(INDEX(INDIRECT(C$6 & "!A:G"),MATCH(Cockpit!$A18,INDIRECT(C$6 & "!A:A"),0),MATCH(C$11,INDIRECT(C$6 & "!1:1"),0))+INDEX(INDIRECT(C$6 & "!A:G"),MATCH(Cockpit!$A18,INDIRECT(C$6 & "!A:A"),0),MATCH(C$12,INDIRECT(C$6 & "!1:1"),0)))/2 -> 1650000 | D18: =LOG((D$9*COUNTIF(B!F:F,Cockpit!A18)-COUNTIFS(B!F:F,Cockpit!A18,B!D:D,"TRAIN") + COUNTIFS(B!F:F,Cockpit!A18,B!D:D,"TRAIN")*D$10)/L18+1) -> 0.0010069088 | E18: =LOG(INDEX(INDIRECT(E$6 & "!A:G"),MATCH(Cockpit!$A18,INDIRECT(E$6 & "!A:A"),0),MATCH(E$11,INDIRECT(E$6 & "!1:1"),0))/L18+1) -> 0.021843079 | F18: =INDEX(INDIRECT(F$6 & "!A:G"),MATCH(Cockpit!$A18,INDIRECT(F$6 & "!A:A"),0),MATCH(F$11,INDIRECT(F$6 & "!1:1"),0)) -> 35 | G18: =LOG((INDEX(INDIRECT(G$6 & "!A:G"),MATCH(Cockpit!$A18,INDIRECT(G$6 & "!A:A"),0),MATCH(G$11,INDIRECT(G$6 & "!1:1"),0))/L18)+1) -> 0.00048509936 | H18: =INDEX(INDIRECT(H$6 & "!A:G"),MATCH(Cockpit!$A18,INDIRECT(H$6 & "!A:A"),0),MATCH(H$11,INDIRECT(H$6 & "!1:1"),0)) -> 62.5 | I18: =LOG(INDEX(INDIRECT(I$6 & "!A:G"),MATCH(Cockpit!$A18,INDIRECT(I$6 & "!A:A"),0),MATCH(I$11,INDIRECT(I$6 & "!1:1"),0))/L18+1) -> 0.00063425175 | K18: Bussigny | L18: 11632
A19: Chavannes-près-Renens | B19: =(INDEX(INDIRECT(B$6 & "!A:G"),MATCH(Cockpit!$A19,INDIRECT(B$6 & "!A:A"),0),MATCH(B$11,INDIRECT(B$6 & "!1:1"),0))+INDEX(INDIRECT(B$6 & "!A:G"),MATCH(Cockpit!$A19,INDIRECT(B$6 & "!A:A"),0),MATCH(B$12,INDIRECT(B$6 & "!1:1"),0)))/2 -> 1350000 | C19: =(INDEX(INDIRECT(C$6 & "!A:G"),MATCH(Cockpit!$A19,INDIRECT(C$6 & "!A:A"),0),MATCH(C$11,INDIRECT(C$6 & "!1:1"),0))+INDEX(INDIRECT(C$6 & "!A:G"),MATCH(Cockpit!$A19,INDIRECT(C$6 & "!A:A"),0),MATCH(C$12,INDIRECT(C$6 & "!1:1"),0)))/2 -> 1550000 | D19: =LOG((D$9*COUNTIF(B!F:F,Cockpit!A19)-COUNTIFS(B!F:F,Cockpit!A19,B!D:D,"TRAIN") + COUNTIFS(B!F:F,Cockpit!A19,B!D:D,"TRAIN")*D$10)/L19+1) -> 0.00079907011 | E19: =LOG(INDEX(INDIRECT(E$6 & "!A:G"),MATCH(Cockpit!$A19,INDIRECT(E$6 & "!A:A"),0),MATCH(E$11,INDIRECT(E$6 & "!1:1"),0))/L19+1) -> 0.020820978 | F19: =INDEX(INDIRECT(F$6 & "!A:G"),MATCH(Cockpit!$A19,INDIRECT(F$6 & "!A:A"),0),MATCH(F$11,INDIRECT(F$6 & "!1:1"),0)) -> 35 | G19: =LOG((INDEX(INDIRECT(G$6 & "!A:G"),MATCH(Cockpit!$A19,INDIRECT(G$6 & "!A:A"),0),MATCH(G$11,INDIRECT(G$6 & "!1:1"),0))/L19)+1) -> 0.00039971883 | H19: =INDEX(INDIRECT(H$6 & "!A:G"),MATCH(Cockpit!$A19,INDIRECT(H$6 & "!A:A"),0),MATCH(H$11,INDIRECT(H$6 & "!1:1"),0)) -> 77.5 | I19: =LOG(INDEX(INDIRECT(I$6 & "!A:G"),MATCH(Cockpit!$A19,INDIRECT(I$6 & "!A:A"),0),MATCH(I$11,INDIRECT(I$6 & "!1:1"),0))/L19+1) -> 0.00031092421 | K19: Chavannes-près-Renens | L19: 9774
A20: Cheseaux-sur-Lausanne | B20: =(INDEX(INDIRECT(B$6 & "!A:G"),MATCH(Cockpit!$A20,INDIRECT(B$6 & "!A:A"),0),MATCH(B$11,INDIRECT(B$6 & "!1:1"),0))+INDEX(INDIRECT(B$6 & "!A:G"),MATCH(Cockpit!$A20,INDIRECT(B$6 & "!A:A"),0),MATCH(B$12,INDIRECT(B$6 & "!1:1"),0)))/2 -> 1150000 | C20: =(INDEX(INDIRECT(C$6 & "!A:G"),MATCH(Cockpit!$A20,INDIRECT(C$6 & "!A:A"),0),MATCH(C$11,INDIRECT(C$6 & "!1:1"),0))+INDEX(INDIRECT(C$6 & "!A:G"),MATCH(Cockpit!$A20,INDIRECT(C$6 & "!A:A"),0),MATCH(C$12,INDIRECT(C$6 & "!1:1"),0)))/2 -> 1550000 | D20: =LOG((D$9*COUNTIF(B!F:F,Cockpit!A20)-COUNTIFS(B!F:F,Cockpit!A20,B!D:D,"TRAIN") + COUNTIFS(B!F:F,Cockpit!A20,B!D:D,"TRAIN")*D$10)/L20+1) -> 0.00062675227 | E20: =LOG(INDEX(INDIRECT(E$6 & "!A:G"),MATCH(Cockpit!$A20,INDIRECT(E$6 & "!A:A"),0),MATCH(E$11,INDIRECT(E$6 & "!1:1"),0))/L20+1) -> 0.024390298 | F20: =INDEX(INDIRECT(F$6 & "!A:G"),MATCH(Cockpit!$A20,INDIRECT(F$6 & "!A:A"),0),MATCH(F$11,INDIRECT(F$6 & "!1:1"),0)) -> 20 | G20: =LOG((INDEX(INDIRECT(G$6 & "!A:G"),MATCH(Cockpit!$A20,INDIRECT(G$6 & "!A:A"),0),MATCH(G$11,INDIRECT(G$6 & "!1:1"),0))/L20)+1) -> 0.00062675227 | H20: =INDEX(INDIRECT(H$6 & "!A:G"),MATCH(Cockpit!$A20,INDIRECT(H$6 & "!A:A"),0),MATCH(H$11,INDIRECT(H$6 & "!1:1"),0)) -> 73 | I20: =LOG(INDEX(INDIRECT(I$6 & "!A:G"),MATCH(Cockpit!$A20,INDIRECT(I$6 & "!A:A"),0),MATCH(I$11,INDIRECT(I$6 & "!1:1"),0))/L20+1) -> 0.00071621452 | K20: Cheseaux-sur-Lausanne | L20: 4847
A21: Crissier | B21: =(INDEX(INDIRECT(B$6 & "!A:G"),MATCH(Cockpit!$A21,INDIRECT(B$6 & "!A:A"),0),MATCH(B$11,INDIRECT(B$6 & "!1:1"),0))+INDEX(INDIRECT(B$6 & "!A:G"),MATCH(Cockpit!$A21,INDIRECT(B$6 & "!A:A"),0),MATCH(B$12,INDIRECT(B$6 & "!1:1"),0)))/2 -> 1250000 | C21: =(INDEX(INDIRECT(C$6 & "!A:G"),MATCH(Cockpit!$A21,INDIRECT(C$6 & "!A:A"),0),MATCH(C$11,INDIRECT(C$6 & "!1:1"),0))+INDEX(INDIRECT(C$6 & "!A:G"),MATCH(Cockpit!$A21,INDIRECT(C$6 & "!A:A"),0),MATCH(C$12,INDIRECT(C$6 & "!1:1"),0)))/2 -> 1650000 | D21: =LOG((D$9*COUNTIF(B!F:F,Cockpit!A21)-COUNTIFS(B!F:F,Cockpit!A21,B!D:D,"TRAIN") + COUNTIFS(B!F:F,Cockpit!A21,B!D:D,"TRAIN")*D$10)/L21+1) -> 0.00077222379 | E21: =LOG(INDEX(INDIRECT(E$6 & "!A:G"),MATCH(Cockpit!$A21,INDIRECT(E$6 & "!A:A"),0),MATCH(E$11,INDIRECT(E$6 & "!1:1"),0))/L21+1) -> 0.021816473 | F21: =INDEX(INDIRECT(F$6 & "!A:G"),MATCH(Cockpit!$A21,INDIRECT(F$6 & "!A:A"),0),MATCH(F$11,INDIRECT(F$6 & "!1:1"),0)) -> 35 | G21: =LOG((INDEX(INDIRECT(G$6 & "!A:G"),MATCH(Cockpit!$A21,INDIRECT(G$6 & "!A:A"),0),MATCH(G$11,INDIRECT(G$6 & "!1:1"),0))/L21)+1) -> 0.00060976443 | H21: =INDEX(INDIRECT(H$6 & "!A:G"),MATCH(Cockpit!$A21,INDIRECT(H$6 & "!A:A"),0),MATCH(H$11,INDIRECT(H$6 & "!1:1"),0)) -> 63.5 | I21: =LOG(INDEX(INDIRECT(I$6 & "!A:G"),MATCH(Cockpit!$A21,INDIRECT(I$6 & "!A:A"),0),MATCH(I$11,INDIRECT(I$6 & "!1:1"),0))/L21+1) -> 0.0012592376 | K21: Crissier | L21: 10676
A22: Cugy | B22: =(INDEX(INDIRECT(B$6 & "!A:G"),MATCH(Cockpit!$A22,INDIRECT(B$6 & "!A:A"),0),MATCH(B$11,INDIRECT(B$6 & "!1:1"),0))+INDEX(INDIRECT(B$6 & "!A:G"),MATCH(Cockpit!$A22,INDIRECT(B$6 & "!A:A"),0),MATCH(B$12,INDIRECT(B$6 & "!1:1"),0)))/2 -> 950000 | C22: =(INDEX(INDIRECT(C$6 & "!A:G"),MATCH(Cockpit!$A22,INDIRECT(C$6 & "!A:A"),0),MATCH(C$11,INDIRECT(C$6 & "!1:1"),0))+INDEX(INDIRECT(C$6 & "!A:G"),MATCH(Cockpit!$A22,INDIRECT(C$6 & "!A:A"),0),MATCH(C$12,INDIRECT(C$6 & "!1:1"),0)))/2 -> 1550000 | D22: =LOG((D$9*COUNTIF(B!F:F,Cockpit!A22)-COUNTIFS(B!F:F,Cockpit!A22,B!D:D,"TRAIN") + COUNTIFS(B!F:F,Cockpit!A22,B!D:D,"TRAIN")*D$10)/L22+1) -> 0 | E22: =LOG(INDEX(INDIRECT(E$6 & "!A:G"),MATCH(Cockpit!$A22,INDIRECT(E$6 & "!A:A"),0),MATCH(E$11,INDIRECT(E$6 & "!1:1"),0))/L22+1) -> 0.027180578 | F22: =INDEX(INDIRECT(F$6 & "!A:G"),MATCH(Cockpit!$A22,INDIRECT(F$6 & "!A:A"),0),MATCH(F$11,INDIRECT(F$6 & "!1:1"),0)) -> 30 | G22: =LOG((INDEX(INDIRECT(G$6 & "!A:G"),MATCH(Cockpit!$A22,INDIRECT(G$6 & "!A:A"),0),MATCH(G$11,INDIRECT(G$6 & "!1:1"),0))/L22)+1) -> 0.00062286778 | H22: =INDEX(INDIRECT(H$6 & "!A:G"),MATCH(Cockpit!$A22,INDIRECT(H$6 & "!A:A"),0),MATCH(H$11,INDIRECT(H$6 & "!1:1"),0)) -> 76 | I22: =LOG(INDEX(INDIRECT(I$6 & "!A:G"),MATCH(Cockpit!$A22,INDIRECT(I$6 & "!A:A"),0),MATCH(I$11,INDIRECT(I$6 & "!1:1"),0))/L22+1) -> 0.00031154555 | K22: Cugy | L22: 2787
A23: Denges | B23: =(INDEX(INDIRECT(B$6 & "!A:G"),MATCH(Cockpit!$A23,INDIRECT(B$6 & "!A:A"),0),MATCH(B$11,INDIRECT(B$6 & "!1:1"),0))+INDEX(INDIRECT(B$6 & "!A:G"),MATCH(Cockpit!$A23,INDIRECT(B$6 & "!A:A"),0),MATCH(B$12,INDIRECT(B$6 & "!1:1"),0)))/2 -> 1350000 | C23: =(INDEX(INDIRECT(C$6 & "!A:G"),MATCH(Cockpit!$A23,INDIRECT(C$6 & "!A:A"),0),MATCH(C$11,INDIRECT(C$6 & "!1:1"),0))+INDEX(INDIRECT(C$6 & "!A:G"),MATCH(Cockpit!$A23,INDIRECT(C$6 & "!A:A"),0),MATCH(C$12,INDIRECT(C$6 & "!1:1"),0)))/2 -> 1950000 | D23: =LOG((D$9*COUNTIF(B!F:F,Cockpit!A23)-COUNTIFS(B!F:F,Cockpit!A23,B!D:D,"TRAIN") + COUNTIFS(B!F:F,Cockpit!A23,B!D:D,"TRAIN")*D$10)/L23+1) -> 0.0031780768 | E23: =LOG(INDEX(INDIRECT(E$6 & "!A:G"),MATCH(Cockpit!$A23,INDIRECT(E$6 & "!A:A"),0),MATCH(E$11,INDIRECT(E$6 & "!1:1"),0))/L23+1) -> 0.033060101 | F23: =INDEX(INDIRECT(F$6 & "!A:G"),MATCH(Cockpit!$A23,INDIRECT(F$6 & "!A:A"),0),MATCH(F$11,INDIRECT(F$6 & "!1:1"),0)) -> 29 | G23: =LOG((INDEX(INDIRECT(G$6 & "!A:G"),MATCH(Cockpit!$A23,INDIRECT(G$6 & "!A:A"),0),MATCH(G$11,INDIRECT(G$6 & "!1:1"),0))/L23)+1) -> 0.00098034913 | H23: =INDEX(INDIRECT(H$6 & "!A:G"),MATCH(Cockpit!$A23,INDIRECT(H$6 & "!A:A"),0),MATCH(H$11,INDIRECT(H$6 & "!1:1"),0)) -> 62 | I23: =LOG(INDEX(INDIRECT(I$6 & "!A:G"),MATCH(Cockpit!$A23,INDIRECT(I$6 & "!A:A"),0),MATCH(I$11,INDIRECT(I$6 & "!1:1"),0))/L23+1) -> 0.0022026817 | K23: Denges | L23: 1770
A24: Echandens | B24: =(INDEX(INDIRECT(B$6 & "!A:G"),MATCH(Cockpit!$A24,INDIRECT(B$6 & "!A:A"),0),MATCH(B$11,INDIRECT(B$6 & "!1:1"),0))+INDEX(INDIRECT(B$6 & "!A:G"),MATCH(Cockpit!$A24,INDIRECT(B$6 & "!A:A"),0),MATCH(B$12,INDIRECT(B$6 & "!1:1"),0)))/2 -> 1450000 | C24: =(INDEX(INDIRECT(C$6 & "!A:G"),MATCH(Cockpit!$A24,INDIRECT(C$6 & "!A:A"),0),MATCH(C$11,INDIRECT(C$6 & "!1:1"),0))+INDEX(INDIRECT(C$6 & "!A:G"),MATCH(Cockpit!$A24,INDIRECT(C$6 & "!A:A"),0),MATCH(C$12,INDIRECT(C$6 & "!1:1"),0)))/2 -> 1950000 | D24: =LOG((D$9*COUNTIF(B!F:F,Cockpit!A24)-COUNTIFS(B!F:F,Cockpit!A24,B!D:D,"TRAIN") + COUNTIFS(B!F:F,Cockpit!A24,B!D:D,"TRAIN")*D$10)/L24+1) -> 0.0011984678 | E24: =LOG(INDEX(INDIRECT(E$6 & "!A:G"),MATCH(Cockpit!$A24,INDIRECT(E$6 & "!A:A"),0),MATCH(E$11,INDIRECT(E$6 & "!1:1"),0))/L24+1) -> 0.031809483 | F24: =INDEX(INDIRECT(F$6 & "!A:G"),MATCH(Cockpit!$A24,INDIRECT(F$6 & "!A:A"),0),MATCH(F$11,INDIRECT(F$6 & "!1:1"),0)) -> 30 | G24: =LOG((INDEX(INDIRECT(G$6 & "!A:G"),MATCH(Cockpit!$A24,INDIRECT(G$6 & "!A:A"),0),MATCH(G$11,INDIRECT(G$6 & "!1:1"),0))/L24)+1) -> 0.00074942984 | H24: =INDEX(INDIRECT(H$6 & "!A:G"),MATCH(Cockpit!$A24,INDIRECT(H$6 & "!A:A"),0),MATCH(H$11,INDIRECT(H$6 & "!1:1"),0)) -> 60.5 | I24: =LOG(INDEX(INDIRECT(I$6 & "!A:G"),MATCH(Cockpit!$A24,INDIRECT(I$6 & "!A:A"),0),MATCH(I$11,INDIRECT(I$6 & "!1:1"),0))/L24+1) -> 0.00089916074 | K24: Echandens | L24: 2895
A25: Ecublens | B25: =(INDEX(INDIRECT(B$6 & "!A:G"),MATCH(Cockpit!$A25,INDIRECT(B$6 & "!A:A"),0),MATCH(B$11,INDIRECT(B$6 & "!1:1"),0))+INDEX(INDIRECT(B$6 & "!A:G"),MATCH(Cockpit!$A25,INDIRECT(B$6 & "!A:A"),0),MATCH(B$12,INDIRECT(B$6 & "!1:1"),0)))/2 -> 1250000 | C25: =(INDEX(INDIRECT(C$6 & "!A:G"),MATCH(Cockpit!$A25,INDIRECT(C$6 & "!A:A"),0),MATCH(C$11,INDIRECT(C$6 & "!1:1"),0))+INDEX(INDIRECT(C$6 & "!A:G"),MATCH(Cockpit!$A25,INDIRECT(C$6 & "!A:A"),0),MATCH(C$12,INDIRECT(C$6 & "!1:1"),0)))/2 -> 2150000 | D25: =LOG((D$9*COUNTIF(B!F:F,Cockpit!A25)-COUNTIFS(B!F:F,Cockpit!A25,B!D:D,"TRAIN") + COUNTIFS(B!F:F,Cockpit!A25,B!D:D,"TRAIN")*D$10)/L25+1) -> 0 | E25: =LOG(INDEX(INDIRECT(E$6 & "!A:G"),MATCH(Cockpit!$A25,INDIRECT(E$6 & "!A:A"),0),MATCH(E$11,INDIRECT(E$6 & "!1:1"),0))/L25+1) -> 0.014697258 | F25: =INDEX(INDIRECT(F$6 & "!A:G"),MATCH(Cockpit!$A25,INDIRECT(F$6 & "!A:A"),0),MATCH(F$11,INDIRECT(F$6 & "!1:1"),0)) -> 35 | G25: =LOG((INDEX(INDIRECT(G$6 & "!A:G"),MATCH(Cockpit!$A25,INDIRECT(G$6 & "!A:A"),0),MATCH(G$11,INDIRECT(G$6 & "!1:1"),0))/L25)+1) -> 0.00058455858 | H25: =INDEX(INDIRECT(H$6 & "!A:G"),MATCH(Cockpit!$A25,INDIRECT(H$6 & "!A:A"),0),MATCH(H$11,INDIRECT(H$6 & "!1:1"),0)) -> 62.5 | I25: =LOG(INDEX(INDIRECT(I$6 & "!A:G"),MATCH(Cockpit!$A25,INDIRECT(I$6 & "!A:A"),0),MATCH(I$11,INDIRECT(I$6 & "!1:1"),0))/L25+1) -> 0.00165421 | K25: Ecublens | L25: 13364
A26: Epalinges | B26: =(INDEX(INDIRECT(B$6 & "!A:G"),MATCH(Cockpit!$A26,INDIRECT(B$6 & "!A:A"),0),MATCH(B$11,INDIRECT(B$6 & "!1:1"),0))+INDEX(INDIRECT(B$6 & "!A:G"),MATCH(Cockpit!$A26,INDIRECT(B$6 & "!A:A"),0),MATCH(B$12,INDIRECT(B$6 & "!1:1"),0)))/2 -> 1350000 | C26: =(INDEX(INDIRECT(C$6 & "!A:G"),MATCH(Cockpit!$A26,INDIRECT(C$6 & "!A:A"),0),MATCH(C$11,INDIRECT(C$6 & "!1:1"),0))+INDEX(INDIRECT(C$6 & "!A:G"),MATCH(Cockpit!$A26,INDIRECT(C$6 & "!A:A"),0),MATCH(C$12,INDIRECT(C$6 & "!1:1"),0)))/2 -> 1850000 | D26: =LOG((D$9*COUNTIF(B!F:F,Cockpit!A26)-COUNTIFS(B!F:F,Cockpit!A26,B!D:D,"TRAIN") + COUNTIFS(B!F:F,Cockpit!A26,B!D:D,"TRAIN")*D$10)/L26+1) -> 0.0010510308 | E26: =LOG(INDEX(INDIRECT(E$6 & "!A:G"),MATCH(Cockpit!$A26,INDIRECT(E$6 & "!A:A"),0),MATCH(E$11,INDIRECT(E$6 & "!1:1"),0))/L26+1) -> 0.031698974 | F26: =INDEX(INDIRECT(F$6 & "!A:G"),MATCH(Cockpit!$A26,INDIRECT(F$6 & "!A:A"),0),MATCH(F$11,INDIRECT(F$6 & "!1:1"),0)) -> 30 | G26: =LOG((INDEX(INDIRECT(G$6 & "!A:G"),MATCH(Cockpit!$A26,INDIRECT(G$6 & "!A:A"),0),MATCH(G$11,INDIRECT(G$6 & "!1:1"),0))/L26)+1) -> 0.00052583336 | H26: =INDEX(INDIRECT(H$6 & "!A:G"),MATCH(Cockpit!$A26,INDIRECT(H$6 & "!A:A"),0),MATCH(H$11,INDIRECT(H$6 & "!1:1"),0)) -> 64.5 | I26: =LOG(INDEX(INDIRECT(I$6 & "!A:G"),MATCH(Cockpit!$A26,INDIRECT(I$6 & "!A:A"),0),MATCH(I$11,INDIRECT(I$6 & "!1:1"),0))/L26+1) -> 0.0032325428 | K26: Epalinges | L26: 9905
A27: Etagnières | B27: =(INDEX(INDIRECT(B$6 & "!A:G"),MATCH(Cockpit!$A27,INDIRECT(B$6 & "!A:A"),0),MATCH(B$11,INDIRECT(B$6 & "!1:1"),0))+INDEX(INDIRECT(B$6 & "!A:G"),MATCH(Cockpit!$A27,INDIRECT(B$6 & "!A:A"),0),MATCH(B$12,INDIRECT(B$6 & "!1:1"),0)))/2 -> 950000 | C27: =(INDEX(INDIRECT(C$6 & "!A:G"),MATCH(Cockpit!$A27,INDIRECT(C$6 & "!A:A"),0),MATCH(C$11,INDIRECT(C$6 & "!1:1"),0))+INDEX(INDIRECT(C$6 & "!A:G"),MATCH(Cockpit!$A27,INDIRECT(C$6 & "!A:A"),0),MATCH(C$12,INDIRECT(C$6 & "!1:1"),0)))/2 -> 1550000 | D27: =LOG((D$9*COUNTIF(B!F:F,Cockpit!A27)-COUNTIFS(B!F:F,Cockpit!A27,B!D:D,"TRAIN") + COUNTIFS(B!F:F,Cockpit!A27,B!D:D,"TRAIN")*D$10)/L27+1) -> 0.0018599364 | E27: =LOG(INDEX(INDIRECT(E$6 & "!A:G"),MATCH(Cockpit!$A27,INDIRECT(E$6 & "!A:A"),0),MATCH(E$11,INDIRECT(E$6 & "!1:1"),0))/L27+1) -> 0.039184259 | F27: =INDEX(INDIRECT(F$6 & "!A:G"),MATCH(Cockpit!$A27,INDIRECT(F$6 & "!A:A"),0),MATCH(F$11,INDIRECT(F$6 & "!1:1"),0)) -> 22 | G27: =LOG((INDEX(INDIRECT(G$6 & "!A:G"),MATCH(Cockpit!$A27,INDIRECT(G$6 & "!A:A"),0),MATCH(G$11,INDIRECT(G$6 & "!1:1"),0))/L27)+1) -> 0.0011169174 | H27: =INDEX(INDIRECT(H$6 & "!A:G"),MATCH(Cockpit!$A27,INDIRECT(H$6 & "!A:A"),0),MATCH(H$11,INDIRECT(H$6 & "!1:1"),0)) -> 73 | I27: =LOG(INDEX(INDIRECT(I$6 & "!A:G"),MATCH(Cockpit!$A27,INDIRECT(I$6 & "!A:A"),0),MATCH(I$11,INDIRECT(I$6 & "!1:1"),0))/L27+1) -> 0.0022309697 | K27: Etagnières | L27: 1165
A28: Forel (Lavaux) | B28: =(INDEX(INDIRECT(B$6 & "!A:G"),MATCH(Cockpit!$A28,INDIRECT(B$6 & "!A:A"),0),MATCH(B$11,INDIRECT(B$6 & "!1:1"),0))+INDEX(INDIRECT(B$6 & "!A:G"),MATCH(Cockpit!$A28,INDIRECT(B$6 & "!A:A"),0),MATCH(B$12,INDIRECT(B$6 & "!1:1"),0)))/2 -> 850000 | C28: =(INDEX(INDIRECT(C$6 & "!A:G"),MATCH(Cockpit!$A28,INDIRECT(C$6 & "!A:A"),0),MATCH(C$11,INDIRECT(C$6 & "!1:1"),0))+INDEX(INDIRECT(C$6 & "!A:G"),MATCH(Cockpit!$A28,INDIRECT(C$6 & "!A:A"),0),MATCH(C$12,INDIRECT(C$6 & "!1:1"),0)))/2 -> 1350000 | D28: =LOG((D$9*COUNTIF(B!F:F,Cockpit!A28)-COUNTIFS(B!F:F,Cockpit!A28,B!D:D,"TRAIN") + COUNTIFS(B!F:F,Cockpit!A28,B!D:D,"TRAIN")*D$10)/L28+1) -> 0.0022060723 | E28: =LOG(INDEX(INDIRECT(E$6 & "!A:G"),MATCH(Cockpit!$A28,INDIRECT(E$6 & "!A:A"),0),MATCH(E$11,INDIRECT(E$6 & "!1:1"),0))/L28+1) -> 0.025381731 | F28: =INDEX(INDIRECT(F$6 & "!A:G"),MATCH(Cockpit!$A28,INDIRECT(F$6 & "!A:A"),0),MATCH(F$11,INDIRECT(F$6 & "!1:1"),0)) -> 30 | G28: =LOG((INDEX(INDIRECT(G$6 & "!A:G"),MATCH(Cockpit!$A28,INDIRECT(G$6 & "!A:A"),0),MATCH(G$11,INDIRECT(G$6 & "!1:1"),0))/L28)+1) -> 0.00060276829 | H28: =INDEX(INDIRECT(H$6 & "!A:G"),MATCH(Cockpit!$A28,INDIRECT(H$6 & "!A:A"),0),MATCH(H$11,INDIRECT(H$6 & "!1:1"),0)) -> 69 | I28: =LOG(INDEX(INDIRECT(I$6 & "!A:G"),MATCH(Cockpit!$A28,INDIRECT(I$6 & "!A:A"),0),MATCH(I$11,INDIRECT(I$6 & "!1:1"),0))/L28+1) -> 0.00060276829 | K28: Forel (Lavaux) | L28: 2160
A29: Lausanne | B29: =(INDEX(INDIRECT(B$6 & "!A:G"),MATCH(Cockpit!$A29,INDIRECT(B$6 & "!A:A"),0),MATCH(B$11,INDIRECT(B$6 & "!1:1"),0))+INDEX(INDIRECT(B$6 & "!A:G"),MATCH(Cockpit!$A29,INDIRECT(B$6 & "!A:A"),0),MATCH(B$12,INDIRECT(B$6 & "!1:1"),0)))/2 -> 1550000 | C29: =(INDEX(INDIRECT(C$6 & "!A:G"),MATCH(Cockpit!$A29,INDIRECT(C$6 & "!A:A"),0),MATCH(C$11,INDIRECT(C$6 & "!1:1"),0))+INDEX(INDIRECT(C$6 & "!A:G"),MATCH(Cockpit!$A29,INDIRECT(C$6 & "!A:A"),0),MATCH(C$12,INDIRECT(C$6 & "!1:1"),0)))/2 -> 2550000 | D29: =LOG((D$9*COUNTIF(B!F:F,Cockpit!A29)-COUNTIFS(B!F:F,Cockpit!A29,B!D:D,"TRAIN") + COUNTIFS(B!F:F,Cockpit!A29,B!D:D,"TRAIN")*D$10)/L29+1) -> 0.00068594504 | E29: =LOG(INDEX(INDIRECT(E$6 & "!A:G"),MATCH(Cockpit!$A29,INDIRECT(E$6 & "!A:A"),0),MATCH(E$11,INDIRECT(E$6 & "!1:1"),0))/L29+1) -> 0.024761459 | F29: =INDEX(INDIRECT(F$6 & "!A:G"),MATCH(Cockpit!$A29,INDIRECT(F$6 & "!A:A"),0),MATCH(F$11,INDIRECT(F$6 & "!1:1"),0)) -> 36 | G29: =LOG((INDEX(INDIRECT(G$6 & "!A:G"),MATCH(Cockpit!$A29,INDIRECT(G$6 & "!A:A"),0),MATCH(G$11,INDIRECT(G$6 & "!1:1"),0))/L29)+1) -> 0.00038953405 | H29: =INDEX(INDIRECT(H$6 & "!A:G"),MATCH(Cockpit!$A29,INDIRECT(H$6 & "!A:A"),0),MATCH(H$11,INDIRECT(H$6 & "!1:1"),0)) -> 78.5 | I29: =LOG(INDEX(INDIRECT(I$6 & "!A:G"),MATCH(Cockpit!$A29,INDIRECT(I$6 & "!A:A"),0),MATCH(I$11,INDIRECT(I$6 & "!1:1"),0))/L29+1) -> 0.0014245947 | K29: Lausanne | L29: 144873 | P29: 900000 | Q29: 1450000 | R29: 0.0010389825 | S29: 0.017832777 | T29: 25 | U29: 0.00051980196 | W29: 70 | X29: 0.025256795 | Y29: Assens | Z29: 1670
A30: Le Mont-sur-Lausanne | B30: =(INDEX(INDIRECT(B$6 & "!A:G"),MATCH(Cockpit!$A30,INDIRECT(B$6 & "!A:A"),0),MATCH(B$11,INDIRECT(B$6 & "!1:1"),0))+INDEX(INDIRECT(B$6 & "!A:G"),MATCH(Cockpit!$A30,INDIRECT(B$6 & "!A:A"),0),MATCH(B$12,INDIRECT(B$6 & "!1:1"),0)))/2 -> 1350000 | C30: =(INDEX(INDIRECT(C$6 & "!A:G"),MATCH(Cockpit!$A30,INDIRECT(C$6 & "!A:A"),0),MATCH(C$11,INDIRECT(C$6 & "!1:1"),0))+INDEX(INDIRECT(C$6 & "!A:G"),MATCH(Cockpit!$A30,INDIRECT(C$6 & "!A:A"),0),MATCH(C$12,INDIRECT(C$6 & "!1:1"),0)))/2 -> 1750000 | D30: =LOG((D$9*COUNTIF(B!F:F,Cockpit!A30)-COUNTIFS(B!F:F,Cockpit!A30,B!D:D,"TRAIN") + COUNTIFS(B!F:F,Cockpit!A30,B!D:D,"TRAIN")*D$10)/L30+1) -> 0.00059196112 | E30: =LOG(INDEX(INDIRECT(E$6 & "!A:G"),MATCH(Cockpit!$A30,INDIRECT(E$6 & "!A:A"),0),MATCH(E$11,INDIRECT(E$6 & "!1:1"),0))/L30+1) -> 0.037100721 | F30: =INDEX(INDIRECT(F$6 & "!A:G"),MATCH(Cockpit!$A30,INDIRECT(F$6 & "!A:A"),0),MATCH(F$11,INDIRECT(F$6 & "!1:1"),0)) -> 30 | G30: =LOG((INDEX(INDIRECT(G$6 & "!A:G"),MATCH(Cockpit!$A30,INDIRECT(G$6 & "!A:A"),0),MATCH(G$11,INDIRECT(G$6 & "!1:1"),0))/L30)+1) -> 0.00091037552 | H30: =INDEX(INDIRECT(H$6 & "!A:G"),MATCH(Cockpit!$A30,INDIRECT(H$6 & "!A:A"),0),MATCH(H$11,INDIRECT(H$6 & "!1:1"),0)) -> 72 | I30: =LOG(INDEX(INDIRECT(I$6 & "!A:G"),MATCH(Cockpit!$A30,INDIRECT(I$6 & "!A:A"),0),MATCH(I$11,INDIRECT(I$6 & "!1:1"),0))/L30+1) -> 0.00068296048 | K30: Le Mont-sur-Lausanne | L30: 9531 | P30: 1250000 | Q30: 1750000 | R30: 0.0028746685 | S30: 0.026883239 | T30: 40 | U30: 0.00044349708 | W30: 72 | X30: 0.00055430063 | Y30: Belmont-sur-Lausanne | Z30: 3915
A31: Lonay | B31: =(INDEX(INDIRECT(B$6 & "!A:G"),MATCH(Cockpit!$A31,INDIRECT(B$6 & "!A:A"),0),MATCH(B$11,INDIRECT(B$6 & "!1:1"),0))+INDEX(INDIRECT(B$6 & "!A:G"),MATCH(Cockpit!$A31,INDIRECT(B$6 & "!A:A"),0),MATCH(B$12,INDIRECT(B$6 & "!1:1"),0)))/2 -> 1350000 | C31: =(INDEX(INDIRECT(C$6 & "!A:G"),MATCH(Cockpit!$A31,INDIRECT(C$6 & "!A:A"),0),MATCH(C$11,INDIRECT(C$6 & "!1:1"),0))+INDEX(INDIRECT(C$6 & "!A:G"),MATCH(Cockpit!$A31,INDIRECT(C$6 & "!A:A"),0),MATCH(C$12,INDIRECT(C$6 & "!1:1"),0)))/2 -> 1850000 | D31: =LOG((D$9*COUNTIF(B!F:F,Cockpit!A31)-COUNTIFS(B!F:F,Cockpit!A31,B!D:D,"TRAIN") + COUNTIFS(B!F:F,Cockpit!A31,B!D:D,"TRAIN")*D$10)/L31+1) -> 0.0032170109 | E31: =LOG(INDEX(INDIRECT(E$6 & "!A:G"),MATCH(Cockpit!$A31,INDIRECT(E$6 & "!A:A"),0),MATCH(E$11,INDIRECT(E$6 & "!1:1"),0))/L31+1) -> 0.03859505 | F31: =INDEX(INDIRECT(F$6 & "!A:G"),MATCH(Cockpit!$A31,INDIRECT(F$6 & "!A:A"),0),MATCH(F$11,INDIRECT(F$6 & "!1:1"),0)) -> 38 | G31: =LOG((INDEX(INDIRECT(G$6 & "!A:G"),MATCH(Cockpit!$A31,INDIRECT(G$6 & "!A:A"),0),MATCH(G$11,INDIRECT(G$6 & "!1:1"),0))/L31)+1) -> 0.00080648952 | H31: =INDEX(INDIRECT(H$6 & "!A:G"),MATCH(Cockpit!$A31,INDIRECT(H$6 & "!A:A"),0),MATCH(H$11,INDIRECT(H$6 & "!1:1"),0)) -> 55 | I31: =LOG(INDEX(INDIRECT(I$6 & "!A:G"),MATCH(Cockpit!$A31,INDIRECT(I$6 & "!A:A"),0),MATCH(I$11,INDIRECT(I$6 & "!1:1"),0))/L31+1) -> 0.015851923 | K31: Lonay | L31: 2690 | P31: 1450000 | Q31: 2150000 | R31: 0.0023217937 | S31: 0.024198764 | T31: 35 | U31: 0.00048139057 | W31: 62.5 | X31: 0.00056157048 | Y31: Bourg-en-Lavaux | Z31: 5410
A32: Lutry | B32: =(INDEX(INDIRECT(B$6 & "!A:G"),MATCH(Cockpit!$A32,INDIRECT(B$6 & "!A:A"),0),MATCH(B$11,INDIRECT(B$6 & "!1:1"),0))+INDEX(INDIRECT(B$6 & "!A:G"),MATCH(Cockpit!$A32,INDIRECT(B$6 & "!A:A"),0),MATCH(B$12,INDIRECT(B$6 & "!1:1"),0)))/2 -> 1550000 | C32: =(INDEX(INDIRECT(C$6 & "!A:G"),MATCH(Cockpit!$A32,INDIRECT(C$6 & "!A:A"),0),MATCH(C$11,INDIRECT(C$6 & "!1:1"),0))+INDEX(INDIRECT(C$6 & "!A:G"),MATCH(Cockpit!$A32,INDIRECT(C$6 & "!A:A"),0),MATCH(C$12,INDIRECT(C$6 & "!1:1"),0)))/2 -> 2400000 | D32: =LOG((D$9*COUNTIF(B!F:F,Cockpit!A32)-COUNTIFS(B!F:F,Cockpit!A32,B!D:D,"TRAIN") + COUNTIFS(B!F:F,Cockpit!A32,B!D:D,"TRAIN")*D$10)/L32+1) -> 0.0019346793 | E32: =LOG(INDEX(INDIRECT(E$6 & "!A:G"),MATCH(Cockpit!$A32,INDIRECT(E$6 & "!A:A"),0),MATCH(E$11,INDIRECT(E$6 & "!1:1"),0))/L32+1) -> 0.023585262 | F32: =INDEX(INDIRECT(F$6 & "!A:G"),MATCH(Cockpit!$A32,INDIRECT(F$6 & "!A:A"),0),MATCH(F$11,INDIRECT(F$6 & "!1:1"),0)) -> 38 | G32: =LOG((INDEX(INDIRECT(G$6 & "!A:G"),MATCH(Cockpit!$A32,INDIRECT(G$6 & "!A:A"),0),MATCH(G$11,INDIRECT(G$6 & "!1:1"),0))/L32)+1) -> 0.00044412585 | H32: =INDEX(INDIRECT(H$6 & "!A:G"),MATCH(Cockpit!$A32,INDIRECT(H$6 & "!A:A"),0),MATCH(H$11,INDIRECT(H$6 & "!1:1"),0)) -> 54 | I32: =LOG(INDEX(INDIRECT(I$6 & "!A:G"),MATCH(Cockpit!$A32,INDIRECT(I$6 & "!A:A"),0),MATCH(I$11,INDIRECT(I$6 & "!1:1"),0))/L32+1) -> 0.0012101842 | K32: Lutry | L32: 10751 | P32: 1150000 | Q32: 1650000 | R32: 0.00072322162 | S32: 0.024622475 | T32: 25 | U32: 0.0014452409 | W32: 68 | X32: 0.00072322162 | Y32: Bremblens | Z32: 600
A33: Morges | B33: =(INDEX(INDIRECT(B$6 & "!A:G"),MATCH(Cockpit!$A33,INDIRECT(B$6 & "!A:A"),0),MATCH(B$11,INDIRECT(B$6 & "!1:1"),0))+INDEX(INDIRECT(B$6 & "!A:G"),MATCH(Cockpit!$A33,INDIRECT(B$6 & "!A:A"),0),MATCH(B$12,INDIRECT(B$6 & "!1:1"),0)))/2 -> 1450000 | C33: =(INDEX(INDIRECT(C$6 & "!A:G"),MATCH(Cockpit!$A33,INDIRECT(C$6 & "!A:A"),0),MATCH(C$11,INDIRECT(C$6 & "!1:1"),0))+INDEX(INDIRECT(C$6 & "!A:G"),MATCH(Cockpit!$A33,INDIRECT(C$6 & "!A:A"),0),MATCH(C$12,INDIRECT(C$6 & "!1:1"),0)))/2 -> 2050000 | D33: =LOG((D$9*COUNTIF(B!F:F,Cockpit!A33)-COUNTIFS(B!F:F,Cockpit!A33,B!D:D,"TRAIN") + COUNTIFS(B!F:F,Cockpit!A33,B!D:D,"TRAIN")*D$10)/L33+1) -> 0.0010020023 | E33: =LOG(INDEX(INDIRECT(E$6 & "!A:G"),MATCH(Cockpit!$A33,INDIRECT(E$6 & "!A:A"),0),MATCH(E$11,INDIRECT(E$6 & "!1:1"),0))/L33+1) -> 0.037482612 | F33: =INDEX(INDIRECT(F$6 & "!A:G"),MATCH(Cockpit!$A33,INDIRECT(F$6 & "!A:A"),0),MATCH(F$11,INDIRECT(F$6 & "!1:1"),0)) -> 38 | G33: =LOG((INDEX(INDIRECT(G$6 & "!A:G"),MATCH(Cockpit!$A33,INDIRECT(G$6 & "!A:A"),0),MATCH(G$11,INDIRECT(G$6 & "!1:1"),0))/L33)+1) -> 0.00073339924 | H33: =INDEX(INDIRECT(H$6 & "!A:G"),MATCH(Cockpit!$A33,INDIRECT(H$6 & "!A:A"),0),MATCH(H$11,INDIRECT(H$6 & "!1:1"),0)) -> 67 | I33: =LOG(INDEX(INDIRECT(I$6 & "!A:G"),MATCH(Cockpit!$A33,INDIRECT(I$6 & "!A:A"),0),MATCH(I$11,INDIRECT(I$6 & "!1:1"),0))/L33+1) -> 0.00073339924 | K33: Morges | L33: 17750 | P33: 1250000 | Q33: 1650000 | R33: 0.0010069088 | S33: 0.021843079 | T33: 35 | U33: 0.00048509936 | W33: 62.5 | X33: 0.00063425175 | Y33: Bussigny | Z33: 11632
A34: Préverenges | B34: =(INDEX(INDIRECT(B$6 & "!A:G"),MATCH(Cockpit!$A34,INDIRECT(B$6 & "!A:A"),0),MATCH(B$11,INDIRECT(B$6 & "!1:1"),0))+INDEX(INDIRECT(B$6 & "!A:G"),MATCH(Cockpit!$A34,INDIRECT(B$6 & "!A:A"),0),MATCH(B$12,INDIRECT(B$6 & "!1:1"),0)))/2 -> 1350000 | C34: =(INDEX(INDIRECT(C$6 & "!A:G"),MATCH(Cockpit!$A34,INDIRECT(C$6 & "!A:A"),0),MATCH(C$11,INDIRECT(C$6 & "!1:1"),0))+INDEX(INDIRECT(C$6 & "!A:G"),MATCH(Cockpit!$A34,INDIRECT(C$6 & "!A:A"),0),MATCH(C$12,INDIRECT(C$6 & "!1:1"),0)))/2 -> 2350000 | D34: =LOG((D$9*COUNTIF(B!F:F,Cockpit!A34)-COUNTIFS(B!F:F,Cockpit!A34,B!D:D,"TRAIN") + COUNTIFS(B!F:F,Cockpit!A34,B!D:D,"TRAIN")*D$10)/L34+1) -> 0.00025000163 | E34: =LOG(INDEX(INDIRECT(E$6 & "!A:G"),MATCH(Cockpit!$A34,INDIRECT(E$6 & "!A:A"),0),MATCH(E$11,INDIRECT(E$6 & "!1:1"),0))/L34+1) -> 0.018761176 | F34: =INDEX(INDIRECT(F$6 & "!A:G"),MATCH(Cockpit!$A34,INDIRECT(F$6 & "!A:A"),0),MATCH(F$11,INDIRECT(F$6 & "!1:1"),0)) -> 38 | G34: =LOG((INDEX(INDIRECT(G$6 & "!A:G"),MATCH(Cockpit!$A34,INDIRECT(G$6 & "!A:A"),0),MATCH(G$11,INDIRECT(G$6 & "!1:1"),0))/L34)+1) -> 0.00049985942 | H34: =INDEX(INDIRECT(H$6 & "!A:G"),MATCH(Cockpit!$A34,INDIRECT(H$6 & "!A:A"),0),MATCH(H$11,INDIRECT(H$6 & "!1:1"),0)) -> 65 | I34: =LOG(INDEX(INDIRECT(I$6 & "!A:G"),MATCH(Cockpit!$A34,INDIRECT(I$6 & "!A:A"),0),MATCH(I$11,INDIRECT(I$6 & "!1:1"),0))/L34+1) -> 0.00066635146 | K34: Préverenges | L34: 5210 | P34: 1350000 | Q34: 1550000 | R34: 0.00079907011 | S34: 0.020820978 | T34: 35 | U34: 0.00039971883 | W34: 77.5 | X34: 0.00031092421 | Y34: Chavannes-près-Renens | Z34: 9774
A35: Prilly | B35: =(INDEX(INDIRECT(B$6 & "!A:G"),MATCH(Cockpit!$A35,INDIRECT(B$6 & "!A:A"),0),MATCH(B$11,INDIRECT(B$6 & "!1:1"),0))+INDEX(INDIRECT(B$6 & "!A:G"),MATCH(Cockpit!$A35,INDIRECT(B$6 & "!A:A"),0),MATCH(B$12,INDIRECT(B$6 & "!1:1"),0)))/2 -> 1350000 | C35: =(INDEX(INDIRECT(C$6 & "!A:G"),MATCH(Cockpit!$A35,INDIRECT(C$6 & "!A:A"),0),MATCH(C$11,INDIRECT(C$6 & "!1:1"),0))+INDEX(INDIRECT(C$6 & "!A:G"),MATCH(Cockpit!$A35,INDIRECT(C$6 & "!A:A"),0),MATCH(C$12,INDIRECT(C$6 & "!1:1"),0)))/2 -> 1650000 | D35: =LOG((D$9*COUNTIF(B!F:F,Cockpit!A35)-COUNTIFS(B!F:F,Cockpit!A35,B!D:D,"TRAIN") + COUNTIFS(B!F:F,Cockpit!A35,B!D:D,"TRAIN")*D$10)/L35+1) -> 0.00071427232 | E35: =LOG(INDEX(INDIRECT(E$6 & "!A:G"),MATCH(Cockpit!$A35,INDIRECT(E$6 & "!A:A"),0),MATCH(E$11,INDIRECT(E$6 & "!1:1"),0))/L35+1) -> 0.021581403 | F35: =INDEX(INDIRECT(F$6 & "!A:G"),MATCH(Cockpit!$A35,INDIRECT(F$6 & "!A:A"),0),MATCH(F$11,INDIRECT(F$6 & "!1:1"),0)) -> 36 | G35: =LOG((INDEX(INDIRECT(G$6 & "!A:G"),MATCH(Cockpit!$A35,INDIRECT(G$6 & "!A:A"),0),MATCH(G$11,INDIRECT(G$6 & "!1:1"),0))/L35)+1) -> 0.00047631205 | H35: =INDEX(INDIRECT(H$6 & "!A:G"),MATCH(Cockpit!$A35,INDIRECT(H$6 & "!A:A"),0),MATCH(H$11,INDIRECT(H$6 & "!1:1"),0)) -> 72.5 | I35: =LOG(INDEX(INDIRECT(I$6 & "!A:G"),MATCH(Cockpit!$A35,INDIRECT(I$6 & "!A:A"),0),MATCH(I$11,INDIRECT(I$6 & "!1:1"),0))/L35+1) -> 0.0013934413 | K35: Prilly | L35: 12758 | P35: 1150000 | Q35: 1550000 | R35: 0.00062675227 | S35: 0.024390298 | T35: 20 | U35: 0.00062675227 | W35: 73 | X35: 0.00071621452 | Y35: Cheseaux-sur-Lausanne | Z35: 4847
A36: Pully | B36: =(INDEX(INDIRECT(B$6 & "!A:G"),MATCH(Cockpit!$A36,INDIRECT(B$6 & "!A:A"),0),MATCH(B$11,INDIRECT(B$6 & "!1:1"),0))+INDEX(INDIRECT(B$6 & "!A:G"),MATCH(Cockpit!$A36,INDIRECT(B$6 & "!A:A"),0),MATCH(B$12,INDIRECT(B$6 & "!1:1"),0)))/2 -> 1700000 | C36: =(INDEX(INDIRECT(C$6 & "!A:G"),MATCH(Cockpit!$A36,INDIRECT(C$6 & "!A:A"),0),MATCH(C$11,INDIRECT(C$6 & "!1:1"),0))+INDEX(INDIRECT(C$6 & "!A:G"),MATCH(Cockpit!$A36,INDIRECT(C$6 & "!A:A"),0),MATCH(C$12,INDIRECT(C$6 & "!1:1"),0)))/2 -> 2250000 | D36: =LOG((D$9*COUNTIF(B!F:F,Cockpit!A36)-COUNTIFS(B!F:F,Cockpit!A36,B!D:D,"TRAIN") + COUNTIFS(B!F:F,Cockpit!A36,B!D:D,"TRAIN")*D$10)/L36+1) -> 0.00097694096 | E36: =LOG(INDEX(INDIRECT(E$6 & "!A:G"),MATCH(Cockpit!$A36,INDIRECT(E$6 & "!A:A"),0),MATCH(E$11,INDIRECT(E$6 & "!1:1"),0))/L36+1) -> 0.023787503 | F36: =INDEX(INDIRECT(F$6 & "!A:G"),MATCH(Cockpit!$A36,INDIRECT(F$6 & "!A:A"),0),MATCH(F$11,INDIRECT(F$6 & "!1:1"),0)) -> 36 | G36: =LOG((INDEX(INDIRECT(G$6 & "!A:G"),MATCH(Cockpit!$A36,INDIRECT(G$6 & "!A:A"),0),MATCH(G$11,INDIRECT(G$6 & "!1:1"),0))/L36)+1) -> 0.00039992332 | H36: =INDEX(INDIRECT(H$6 & "!A:G"),MATCH(Cockpit!$A36,INDIRECT(H$6 & "!A:A"),0),MATCH(H$11,INDIRECT(H$6 & "!1:1"),0)) -> 61 | I36: =LOG(INDEX(INDIRECT(I$6 & "!A:G"),MATCH(Cockpit!$A36,INDIRECT(I$6 & "!A:A"),0),MATCH(I$11,INDIRECT(I$6 & "!1:1"),0))/L36+1) -> 0.00073291167 | K36: Pully | L36: 19538 | P36: 1250000 | Q36: 1650000 | R36: 0.00077222379 | S36: 0.021816473 | T36: 35 | U36: 0.00060976443 | W36: 63.5 | X36: 0.0012592376 | Y36: Crissier | Z36: 10676
A37: Renens | B37: =(INDEX(INDIRECT(B$6 & "!A:G"),MATCH(Cockpit!$A37,INDIRECT(B$6 & "!A:A"),0),MATCH(B$11,INDIRECT(B$6 & "!1:1"),0))+INDEX(INDIRECT(B$6 & "!A:G"),MATCH(Cockpit!$A37,INDIRECT(B$6 & "!A:A"),0),MATCH(B$12,INDIRECT(B$6 & "!1:1"),0)))/2 -> 1250000 | C37: =(INDEX(INDIRECT(C$6 & "!A:G"),MATCH(Cockpit!$A37,INDIRECT(C$6 & "!A:A"),0),MATCH(C$11,INDIRECT(C$6 & "!1:1"),0))+INDEX(INDIRECT(C$6 & "!A:G"),MATCH(Cockpit!$A37,INDIRECT(C$6 & "!A:A"),0),MATCH(C$12,INDIRECT(C$6 & "!1:1"),0)))/2 -> 1850000 | D37: =LOG((D$9*COUNTIF(B!F:F,Cockpit!A37)-COUNTIFS(B!F:F,Cockpit!A37,B!D:D,"TRAIN") + COUNTIFS(B!F:F,Cockpit!A37,B!D:D,"TRAIN")*D$10)/L37+1) -> 0 | E37: =LOG(INDEX(INDIRECT(E$6 & "!A:G"),MATCH(Cockpit!$A37,INDIRECT(E$6 & "!A:A"),0),MATCH(E$11,INDIRECT(E$6 & "!1:1"),0))/L37+1) -> 0.018742905 | F37: =INDEX(INDIRECT(F$6 & "!A:G"),MATCH(Cockpit!$A37,INDIRECT(F$6 & "!A:A"),0),MATCH(F$11,INDIRECT(F$6 & "!1:1"),0)) -> 36 | G37: =LOG((INDEX(INDIRECT(G$6 & "!A:G"),MATCH(Cockpit!$A37,INDIRECT(G$6 & "!A:A"),0),MATCH(G$11,INDIRECT(G$6 & "!1:1"),0))/L37)+1) -> 0.00044332217 | H37: =INDEX(INDIRECT(H$6 & "!A:G"),MATCH(Cockpit!$A37,INDIRECT(H$6 & "!A:A"),0),MATCH(H$11,INDIRECT(H$6 & "!1:1"),0)) -> 77 | I37: =LOG(INDEX(INDIRECT(I$6 & "!A:G"),MATCH(Cockpit!$A37,INDIRECT(I$6 & "!A:A"),0),MATCH(I$11,INDIRECT(I$6 & "!1:1"),0))/L37+1) -> 0.00074532804 | K37: Renens | L37: 21541 | P37: 950000 | Q37: 1550000 | R37: 0 | S37: 0.027180578 | T37: 30 | U37: 0.00062286778 | W37: 76 | X37: 0.00031154555 | Y37: Cugy | Z37: 2787
A38: Saint-Barthélemy | B38: =(INDEX(INDIRECT(B$6 & "!A:G"),MATCH(Cockpit!$A38,INDIRECT(B$6 & "!A:A"),0),MATCH(B$11,INDIRECT(B$6 & "!1:1"),0))+INDEX(INDIRECT(B$6 & "!A:G"),MATCH(Cockpit!$A38,INDIRECT(B$6 & "!A:A"),0),MATCH(B$12,INDIRECT(B$6 & "!1:1"),0)))/2 -> 700000 | C38: =(INDEX(INDIRECT(C$6 & "!A:G"),MATCH(Cockpit!$A38,INDIRECT(C$6 & "!A:A"),0),MATCH(C$11,INDIRECT(C$6 & "!1:1"),0))+INDEX(INDIRECT(C$6 & "!A:G"),MATCH(Cockpit!$A38,INDIRECT(C$6 & "!A:A"),0),MATCH(C$12,INDIRECT(C$6 & "!1:1"),0)))/2 -> 1250000 | D38: =LOG((D$9*COUNTIF(B!F:F,Cockpit!A38)-COUNTIFS(B!F:F,Cockpit!A38,B!D:D,"TRAIN") + COUNTIFS(B!F:F,Cockpit!A38,B!D:D,"TRAIN")*D$10)/L38+1) -> 0 | E38: =LOG(INDEX(INDIRECT(E$6 & "!A:G"),MATCH(Cockpit!$A38,INDIRECT(E$6 & "!A:A"),0),MATCH(E$11,INDIRECT(E$6 & "!1:1"),0))/L38+1) -> 0.021189299 | F38: =INDEX(INDIRECT(F$6 & "!A:G"),MATCH(Cockpit!$A38,INDIRECT(F$6 & "!A:A"),0),MATCH(F$11,INDIRECT(F$6 & "!1:1"),0)) -> 25 | G38: =LOG((INDEX(INDIRECT(G$6 & "!A:G"),MATCH(Cockpit!$A38,INDIRECT(G$6 & "!A:A"),0),MATCH(G$11,INDIRECT(G$6 & "!1:1"),0))/L38)+1) -> 0.0010843813 | H38: =INDEX(INDIRECT(H$6 & "!A:G"),MATCH(Cockpit!$A38,INDIRECT(H$6 & "!A:A"),0),MATCH(H$11,INDIRECT(H$6 & "!1:1"),0)) -> 77 | I38: =LOG(INDEX(INDIRECT(I$6 & "!A:G"),MATCH(Cockpit!$A38,INDIRECT(I$6 & "!A:A"),0),MATCH(I$11,INDIRECT(I$6 & "!1:1"),0))/L38+1) -> 0.0027058934 | K38: Saint-Barthélemy | L38: 800 | P38: 1350000 | Q38: 1950000 | R38: 0.0031780768 | S38: 0.033060101 | T38: 29 | U38: 0.00098034913 | W38: 62 | X38: 0.0022026817 | Y38: Denges | Z38: 1770
A39: Sainte-Croix | B39: =(INDEX(INDIRECT(B$6 & "!A:G"),MATCH(Cockpit!$A39,INDIRECT(B$6 & "!A:A"),0),MATCH(B$11,INDIRECT(B$6 & "!1:1"),0))+INDEX(INDIRECT(B$6 & "!A:G"),MATCH(Cockpit!$A39,INDIRECT(B$6 & "!A:A"),0),MATCH(B$12,INDIRECT(B$6 & "!1:1"),0)))/2 -> 450000 | C39: =(INDEX(INDIRECT(C$6 & "!A:G"),MATCH(Cockpit!$A39,INDIRECT(C$6 & "!A:A"),0),MATCH(C$11,INDIRECT(C$6 & "!1:1"),0))+INDEX(INDIRECT(C$6 & "!A:G"),MATCH(Cockpit!$A39,INDIRECT(C$6 & "!A:A"),0),MATCH(C$12,INDIRECT(C$6 & "!1:1"),0)))/2 -> 850000 | D39: =LOG((D$9*COUNTIF(B!F:F,Cockpit!A39)-COUNTIFS(B!F:F,Cockpit!A39,B!D:D,"TRAIN") + COUNTIFS(B!F:F,Cockpit!A39,B!D:D,"TRAIN")*D$10)/L39+1) -> 0.0026789716 | E39: =LOG(INDEX(INDIRECT(E$6 & "!A:G"),MATCH(Cockpit!$A39,INDIRECT(E$6 & "!A:A"),0),MATCH(E$11,INDIRECT(E$6 & "!1:1"),0))/L39+1) -> 0.029327064 | F39: =INDEX(INDIRECT(F$6 & "!A:G"),MATCH(Cockpit!$A39,INDIRECT(F$6 & "!A:A"),0),MATCH(F$11,INDIRECT(F$6 & "!1:1"),0)) -> 23 | G39: =LOG((INDEX(INDIRECT(G$6 & "!A:G"),MATCH(Cockpit!$A39,INDIRECT(G$6 & "!A:A"),0),MATCH(G$11,INDIRECT(G$6 & "!1:1"),0))/L39)+1) -> 0.00077946981 | H39: =INDEX(INDIRECT(H$6 & "!A:G"),MATCH(Cockpit!$A39,INDIRECT(H$6 & "!A:A"),0),MATCH(H$11,INDIRECT(H$6 & "!1:1"),0)) -> 70 | I39: =LOG(INDEX(INDIRECT(I$6 & "!A:G"),MATCH(Cockpit!$A39,INDIRECT(I$6 & "!A:A"),0),MATCH(I$11,INDIRECT(I$6 & "!1:1"),0))/L39+1) -> 0.0037115724 | K39: Sainte-Croix | L39: 5010 | P39: 1450000 | Q39: 1950000 | R39: 0.0011984678 | S39: 0.031809483 | T39: 30 | U39: 0.00074942984 | W39: 60.5 | X39: 0.00089916074 | Y39: Echandens | Z39: 2895
A40: Saint-Sulpice | B40: =(INDEX(INDIRECT(B$6 & "!A:G"),MATCH(Cockpit!$A40,INDIRECT(B$6 & "!A:A"),0),MATCH(B$11,INDIRECT(B$6 & "!1:1"),0))+INDEX(INDIRECT(B$6 & "!A:G"),MATCH(Cockpit!$A40,INDIRECT(B$6 & "!A:A"),0),MATCH(B$12,INDIRECT(B$6 & "!1:1"),0)))/2 -> 1450000 | C40: =(INDEX(INDIRECT(C$6 & "!A:G"),MATCH(Cockpit!$A40,INDIRECT(C$6 & "!A:A"),0),MATCH(C$11,INDIRECT(C$6 & "!1:1"),0))+INDEX(INDIRECT(C$6 & "!A:G"),MATCH(Cockpit!$A40,INDIRECT(C$6 & "!A:A"),0),MATCH(C$12,INDIRECT(C$6 & "!1:1"),0)))/2 -> 2750000 | D40: =LOG((D$9*COUNTIF(B!F:F,Cockpit!A40)-COUNTIFS(B!F:F,Cockpit!A40,B!D:D,"TRAIN") + COUNTIFS(B!F:F,Cockpit!A40,B!D:D,"TRAIN")*D$10)/L40+1) -> 0 | E40: =LOG(INDEX(INDIRECT(E$6 & "!A:G"),MATCH(Cockpit!$A40,INDIRECT(E$6 & "!A:A"),0),MATCH(E$11,INDIRECT(E$6 & "!1:1"),0))/L40+1) -> 0.024566085 | F40: =INDEX(INDIRECT(F$6 & "!A:G"),MATCH(Cockpit!$A40,INDIRECT(F$6 & "!A:A"),0),MATCH(F$11,INDIRECT(F$6 & "!1:1"),0)) -> 28 | G40: =LOG((INDEX(INDIRECT(G$6 & "!A:G"),MATCH(Cockpit!$A40,INDIRECT(G$6 & "!A:A"),0),MATCH(G$11,INDIRECT(G$6 & "!1:1"),0))/L40)+1) -> 0.00075756397 | H40: =INDEX(INDIRECT(H$6 & "!A:G"),MATCH(Cockpit!$A40,INDIRECT(H$6 & "!A:A"),0),MATCH(H$11,INDIRECT(H$6 & "!1:1"),0)) -> 55 | I40: =LOG(INDEX(INDIRECT(I$6 & "!A:G"),MATCH(Cockpit!$A40,INDIRECT(I$6 & "!A:A"),0),MATCH(I$11,INDIRECT(I$6 & "!1:1"),0))/L40+1) -> 0.0015138088 | K40: Saint-Sulpice | L40: 5155 | P40: 1250000 | Q40: 2150000 | R40: 0 | S40: 0.014697258 | T40: 35 | U40: 0.00058455858 | W40: 62.5 | X40: 0.00165421 | Y40: Ecublens | Z40: 13364
...

Sheet A
A1: Commune | B1: Appart. Prix bas | C1: Appart. Prix haut | D1: Maison prix bas | E1: Maison prix haut
A2: Assens | B2: 800000 | C2: 1000000 | D2: 1400000 | E2: 1500000
A3: Belmont-sur-Lausanne | B3: 1200000 | C3: 1300000 | D3: 1700000 | E3: 1800000
A4: Bourg-en-Lavaux | B4: 1400000 | C4: 1500000 | D4: 2100000 | E4: 2200000
A5: Bremblens | B5: 1100000 | C5: 1200000 | D5: 1600000 | E5: 1700000
A6: Bussigny | B6: 1200000 | C6: 1300000 | D6: 1600000 | E6: 1700000
A7: Chavannes-près-Renens | B7: 1300000 | C7: 1400000 | D7: 1500000 | E7: 1600000
A8: Cheseaux-sur-Lausanne | B8: 1100000 | C8: 1200000 | D8: 1500000 | E8: 1600000
A9: Crissier | B9: 1200000 | C9: 1300000 | D9: 1600000 | E9: 1700000
A10: Cugy | B10: 900000 | C10: 1000000 | D10: 1500000 | E10: 1600000
A11: Denges | B11: 1300000 | C11: 1400000 | D11: 1900000 | E11: 2000000
A12: Echandens | B12: 1400000 | C12: 1500000 | D12: 1900000 | E12: 2000000
A13: Ecublens | B13: 1200000 | C13: 1300000 | D13: 2100000 | E13: 2200000
... A31: Vaulion | B31: 300000 | C31: 400000 | D31: 600000 | E31: 700000

Sheet A1
A1: Commune | B1: Appart. Prix bas | C1: Appart. Prix haut | D1: Maison prix bas | E1: Maison prix haut
A2: Assens | B2: 800000 | C2: 1000000 | D2: 1400000 | E2: 1500000
A3: Belmont-sur-Lausanne | B3: 1200000 | C3: 1300000 | D3: 1700000 | E3: 1800000
A4: Bourg-en-Lavaux | B4: 1400000 | C4: 1500000 | D4: 2100000 | E4: 2200000
A5: Bremblens | B5: 1100000 | C5: 1200000 | D5: 1600000 | E5: 1700000
A6: Bussigny | B6: 1200000 | C6: 1300000 | D6: 1600000 | E6: 1700000
A7: Chavannes-près-Renens | B7: 1300000 | C7: 1400000 | D7: 1500000 | E7: 1600000
A8: Cheseaux-sur-Lausanne | B8: 1100000 | C8: 1200000 | D8: 1500000 | E8: 1600000
A9: Crissier | B9: 1200000 | C9: 1300000 | D9: 1600000 | E9: 1700000
A10: Cugy | B10: 900000 | C10: 1000000 | D10: 1500000 | E10: 1600000
A11: Denges | B11: 1300000 | C11: 1400000 | D11: 1900000 | E11: 2000000
A12: Echandens | B12: 1400000 | C12: 1500000 | D12: 1900000 | E12: 2000000
A13: Ecublens | B13: 1200000 | C13: 1300000 | D13: 2100000 | E13: 2200000
... A31: Vaulion | B31: 300000 | C31: 400000 | D31: 600000 | E31: 700000

Sheet B
A1: Code DiDok | B1: Désignation officielle | C1: Désignation organisation commerciale | D1: Moyen de transport | E1: Canton | F1: Commune | G1: Numéro Commune | H1: Localité | I1: Swiss Business Organisation ID | J1: Commentaire OFT | K1: Coordonnées E MN95 | L1: Coordonnées N MN95 | M1: Altitude | N1: Lien sur la carte
A2: 8583891 | B2: Vufflens-Aclens, zone industr. | C2: Automobiles MBC | D2: BUS | E2: VD | F2: Aclens | G2: 5621 | H2: Aclens | I2: ch:1:sboid:100566 | K2: 2529929.7 | L2: 1157464 | M2: 406 | N2: 46.56477268818526, 6.524742392767344
A3: 8570093 | B3: Aclens, collège | C3: Automobiles MBC | D3: BUS | E3: VD | F3: Aclens | G3: 5621 | H3: Aclens | I3: ch:1:sboid:100566 | K3: 2528825 | L3: 1157750 | M3: 450 | N3: 46.567228572318456, 6.510291141153921
A4: 8507650 | B4: Agiez, Vers-le-Pont | C4: PostAuto AG | D4: BUS | E4: VD | F4: Agiez | G4: 5742 | H4: Agiez | I4: ch:1:sboid:100602 | K4: 2529106 | L4: 1174641 | M4: 507 | N4: 46.71919129431517, 6.511347735082323
A5: 8570235 | B5: Agiez, L'Epine | C5: PostAuto AG | D5: BUS | E5: VD | F5: Agiez | G5: 5742 | H5: Agiez | I5: ch:1:sboid:100602 | K5: 2528837 | L5: 1174270 | M5: 523 | N5: 46.71582551025668, 6.507887226046329
A6: 8504425 | B6: Aigle, Les Iles | C6: Transports Publics du Chablais (Bus) | D6: BUS | E6: VD | F6: Aigle | G6: 5401 | H6: Aigle | I6: ch:1:sboid:100617 | K6: 2562250 | L6: 1127697 | M6: 386 | N6: 46.29961661730584, 6.948697073079572
A7: 8505193 | B7: Aigle, Biole | C7: Transports Publics du Chablais (Bus) | D7: BUS | E7: VD | F7: Aigle | G7: 5401 | H7: Aigle | I7: ch:1:sboid:100617 | K7: 2561991 | L7: 1128843 | M7: 384 | N7: 46.309910755987055, 6.945241890286049
A8: 8581845 | B8: Aigle, collège Planchette | C8: Transports Publics du Chablais (Bus) | D8: BUS | E8: VD | F8: Aigle | G8: 5401 | H8: Aigle | I8: ch:1:sboid:100617 | J8: (Bus) ohne Fahrplandaten 2016 [beibehalten] | K8: 2562877 | L8: 1129904 | M8: 396 | N8: 46.31950460015498, 6.956658085456567
A9: 8517484 | B9: Aigle-Parc Aventure | C9: Transports Publics du Chablais | D9: TRAIN | E9: VD | F9: Aigle | G9: 5401 | H9: Aigle | I9: ch:1:sboid:100008 | K9: 2565151.2 | L9: 1129423 | M9: 488.1 | N9: 46.315300001126964, 6.986219994119313
A10: 8581047 | B10: Aigle, Pautex | C10: Transports Publics du Chablais (Bus) | D10: BUS | E10: VD | F10: Aigle | G10: 5401 | H10: Aigle | I10: ch:1:sboid:100617 | K10: 2562697 | L10: 1129618 | M10: 393 | N10: 46.31692190321954, 6.954344102473771
A11: 8593763 | B11: Aigle, av. Margencel | C11: Transports Publics du Chablais (Bus) | D11: BUS | E11: VD | F11: Aigle | G11: 5401 | H11: Aigle | I11: ch:1:sboid:100617 | K11: 2563515 | L11: 1129751 | M11: 406 | N11: 46.318163343780725, 6.964953361332843
A12: 8511106 | B12: Aigle-Dépôt, gare | C12: Transports Publics du Chablais (Bus) | D12: BUS | E12: VD | F12: Aigle | G12: 5401 | H12: Aigle | I12: ch:1:sboid:100617 | K12: 2564331 | L12: 1129735 | M12: 428 | N12: 46.31806335872635, 6.975548588579126
A13: 8512177 | B13: Aigle, Fontanney | C13: Transports Publics du Chablais (Bus) | D13: BUS | E13: VD | F13: Aigle | G13: 5401 | H13: Aigle | I13: ch:1:sboid:100617 | K13: 2565332.6 | L13: 1129785.5 | M13: 532.5 | N13: 46.31857051500889, 6.988548107424288
A14: 8593766 | B14: Aigle, Dents-du-Midi | C14: Transports Publics du Chablais (Bus) | D14: BUS | E14: VD | F14: Aigle | G14: 5401 | H14: Aigle | I14: ch:1:sboid:100617 | K14: 2563046 | L14: 1129261 | M14: 396 | N14: 46.313729866550396, 6.9589034211079
A15: 8593765 | B15: Aigle, Champex | C15: Transports Publics du Chablais (Bus) | D15: BUS | E15: VD | F15: Aigle | G15: 5401 | H15: Aigle | I15: ch:1:sboid:100617 | K15: 2561857 | L15: 1129051 | M15: 383 | N15: 46.31177419397323, 6.943485372920066
A16: 8593764 | B16: Aigle, ch. des Lieugex | C16: Transports Publics du Chablais (Bus) | D16: BUS | E16: VD | F16: Aigle | G16: 5401 | H16: Aigle | I16: ch:1:sboid:100617 | K16: 2563147 | L16: 1129978 | M16: 401 | N16: 46.3201851703714, 6.960157659596822
A17: 8517500 | B17: Aigle-Place-du-Marché (DIAB) | C17: Transports Publics du Chablais | E17: VD | F17: Aigle | G17: 5401 | H17: Aigle | I17: ch:1:sboid:100008 | J17: (Zug) | K17: 2563889.6 | L17: 1129585 | M17: 415.3 | N17: 46.31668999858064, 6.969829998461089
A18: 8501400 | B18: Aigle | C18: Schweizerische Bundesbahnen SBB | D18: TRAIN | E18: VD | F18: Aigle | G18: 5401 | H18: Aigle | I18: ch:1:sboid:100001 | K18: 2563416.3 | L18: 1129606.2 | M18: 403.908 | N18: 46.316855418598124, 6.963683211861402
A19: 8501468 | B19: Aigle-Château | C19: Transports Publics du Chablais | D19: TRAIN | E19: VD | F19: Aigle | G19: 5401 | H19: Aigle | I19: ch:1:sboid:100008 | K19: 2564590 | L19: 1129601 | M19: 433 | N19: 46.31687170607126, 6.97892136108901
A20: 8501554 | B20: Aigle-Place-du-Marché | C20: Transports Publics du Chablais | D20: TRAIN | E20: VD | F20: Aigle | G20: 5401 | H20: Aigle | I20: ch:1:sboid:100008 | K20: 2563929.3 | L20: 1129645.9 | M20: 416.7 | N20: 46.317239994000715, 6.970339995448264
A21: 8509014 | B21: Aigle, Pré Neyroud | C21: Transports Publics du Chablais (Bus) | D21: BUS | E21: VD | F21: Aigle | G21: 5401 | H21: Aigle | I21: ch:1:sboid:100617 | K21: 2561952 | L21: 1127942 | M21: 385 | N21: 46.3018036496258, 6.944809449285151
A22: 8570600 | B22: Aigle, gare | C22: Transports Publics du Chablais (Bus) | D22: BUS | E22: VD | F22: Aigle | G22: 5401 | H22: Aigle | I22: ch:1:sboid:100617 | K22: 2563487 | L22: 1129528 | M22: 406 | N22: 46.31615583128023, 6.964607382328524
A23: 8570601 | B23: Aigle, place du Marché | C23: Transports Publics du Chablais (Bus) | D23: BUS | E23: VD | F23: Aigle | G23: 5401 | H23: Aigle | I23: ch:1:sboid:100617 | K23: 2563920 | L23: 1129661 | M23: 417 | N23: 46.31737568585273, 6.9702184049401295
A24: 8501179 | B24: Pont-de-Drapel | C24: Transports Publics du Chablais | D24: TRAIN | E24: VD | F24: Aigle | G24: 5401 | H24: Aigle | I24: ch:1:sboid:100008 | K24: 2565177.2 | L24: 1129929.8 | M24: 613.7 | N24: 46.31985999970431, 6.986520004273106
A25: 8501485 | B25: Fontanney | C25: Transports Publics du Chablais | D25: TRAIN | E25: VD | F25: Aigle | G25: 5401 | H25: Aigle | I25: ch:1:sboid:100008 | K25: 2564851.2 | L25: 1129760.5 | M25: 548.8 | N25: 46.31831999450118, 6.982299999546069
A26: 8504407 | B26: Aigle, Grand-Pré | C26: Transports Publics du Chablais (Bus) | D26: BUS | E26: VD | F26: Aigle | G26: 5401 | H26: Aigle | I26: ch:1:sboid:100617 | K26: 2561407 | L26: 1129616 | M26: 383 | N26: 46.316830850819, 6.9375968369801955
A27: 8504421 | B27: Aigle, Levant | C27: Transports Publics du Chablais (Bus) | D27: BUS | E27: VD | F27: Aigle | G27: 5401 | H27: Aigle | I27: ch:1:sboid:100617 | K27: 2563107 | L27: 1129587 | M27: 399 | N27: 46.31666574611651, 6.95966940254503
A28: 8511997 | B28: RBC Chablais | C28: Schweizerische Bundesbahnen SBB | E28: VD | F28: Aigle | G28: 5401 | H28: Aigle | I28: ch:1:sboid:100001 | K28: 2563339.5 | L28: 1130262.2 | M28: 405.9 | N28: 46.3227520902552, 6.9626350459755155
A29: 8593770 | B29: Aigle, Pré d'Emoz/écoles | C29: Transports Publics du Chablais (Bus) | D29: BUS | E29: VD | F29: Aigle | G29: 5401 | H29: Aigle | I29: ch:1:sboid:100617 | K29: 2562865 | L29: 1130145 | M29: 397 | N29: 46.32167183919654, 6.956483007024112
A30: 8593769 | B30: Aigle, Novassales | C30: Transports Publics du Chablais (Bus) | D30: BUS | E30: VD | F30: Aigle | G30: 5401 | H30: Aigle | I30: ch:1:sboid:100617 | K30: 2563342 | L30: 1129352 | M30: 403 | N30: 46.31456471306193, 6.962738839240221
A31: 8593768 | B31: Aigle, Vergers | C31: Transports Publics du Chablais (Bus) | D31: BUS | E31: VD | F31: Aigle | G31: 5401 | H31: Aigle | I31: ch:1:sboid:100617 | J31: bis 2018: Aigle, hôpital | K31: 2563407 | L31: 1129066 | M31: 401 | N31: 46.31199556571619, 6.9636052087107245
A32: 8581046 | B32: Aigle, rte d'Evian | C32: Transports Publics du Chablais (Bus) | D32: BUS | E32: VD | F32: Aigle | G32: 5401 | H32: Aigle | I32: ch:1:sboid:100617 | K32: 2563043 | L32: 1129759 | M32: 399 | N32: 46.318209436951534, 6.958824831624484
A33: 8581050 | B33: Aigle, La Mêlée | C33: PostAuto AG | D33: BUS | E33: VD | F33: Aigle | G33: 5401 | H33: Aigle | I33: ch:1:sboid:100602 | K33: 2561446 | L33: 1129765 | M33: 385 | N33: 46.31817341640464, 6.938090780183085
A34: 8511103 | B34: Aigle, Valerette | C34: Transports Publics du Chablais (Bus) | D34: BUS | E34: VD | F34: Aigle | G34: 5401 | H34: Aigle | I34: ch:1:sboid:100617 | K34: 2563701 | L34: 1128915 | M34: 404 | N34: 46.31065324343813, 6.967433533095001
A35: 8519338 | B35: Aigle [voie 11-16] | C35: Transports Publics du Chablais | E35: VD | F35: Aigle | G35: 5401 | H35: Aigle | I35: ch:1:sboid:100008 | J35: (Zug) | K35: 2563448 | L35: 1129549 | M35: 404 | N35: 46.316342609309636, 6.964099417232659
A36: 8581048 | B36: Aigle, Golf | C36: Transports Publics du Chablais (Bus) | D36: BUS | E36: VD | F36: Aigle | G36: 5401 | H36: Aigle | I36: ch:1:sboid:100617 | K36: 2562291 | L36: 1129451 | M36: 388 | N36: 46.315396936375215, 6.949086764936207
A37: 8501484 | B37: Aigle-Dépôt | C37: Transports Publics du Chablais | D37: TRAIN | E37: VD | F37: Aigle | G37: 5401 | H37: Aigle | I37: ch:1:sboid:100008 | K37: 2564317.4 | L37: 1129760.3 | M37: 427.6 | N37: 46.318289994546745, 6.975370001409716
A38: 8596090 | B38: Aigle, Les Glariers | C38: Transports Publics du Chablais (Bus) | D38: BUS | E38: VD | F38: Aigle | G38: 5401 | H38: Aigle | I38: ch:1:sboid:100617 | J38: (neue Hst per 12.2017 aber keine Fahrplandaten) | K38: 2563730 | L38: 1130027 | M38: 412 | N38: 46.32065776499928, 6.967723103787464
A39: 8501471 | B39: Plambuit | C39: Transports Publics du Chablais | D39: TRAIN | E39: VD | F39: Aigle | G39: 5401 | H39: Aigle | I39: ch:1:sboid:100008 | K39: 2568066 | L39: 1130746.4 | M39: 801.4 | N39: 46.32734999369797, 7.023969993526004
A40: 8504408 | B40: Aigle, piscine | C40: Transports Publics du Chablais (Bus) | D40: BUS | E40: VD | F40: Aigle | G40: 5401 | H40: Aigle | I40: ch:1:sboid:100617 | K40: 2563338 | L40: 1130162 | M40: 404 | N40: 46.32185081398912, 6.962622938313034
...

Sheet C
A1: Commune | B1: Nombre approx. d'établissements commerciaux | G1: Prompt ia google | H1: # donne moi simplement le nombre de commerce par commune pour cette liste
A2: Assens | B2: 70
A3: Belmont-sur-Lausanne | B3: 250
A4: Bourg-en-Lavaux | B4: 310
A5: Bremblens | B5: 35
A6: Bussigny | B6: 600
A7: Chavannes-près-Renens | B7: 480
A8: Cheseaux-sur-Lausanne | B8: 280
A9: Crissier | B9: 550
A10: Cugy | B10: 180
A11: Denges | B11: 140
A12: Echandens | B12: 220
A13: Ecublens | B13: 460
... A31: Vaulion | B31: 450

Sheet D
A1: Commune | B1: Indice (IQA) | C1: Qualité | F1: IQA (Indice de Qualité de l'Air) : Indicateur numérique standardisé mesurant la concentration de polluants atmosphériques (particules fines, ozone, | I1: ). Un score de 0 à 50 est considéré comme Bon (aucun risque). Plus l'indice est élevé, plus la pollution est importante. | S1: Source, prompt IA Google
A2: Assens | B2: 25 | C2: Bonne
A3: Belmont-sur-Lausanne | B3: 40 | C3: Bonne
A4: Bourg-en-Lavaux | B4: 35 | C4: Bonne
A5: Bremblens | B5: 25 | C5: Excellente
A6: Bussigny | B6: 35 | C6: Bonne
A7: Chavannes-près-Renens | B7: 35 | C7: Bonne
A8: Cheseaux-sur-Lausanne | B8: 20 | C8: Bonne
A9: Crissier | B9: 35 | C9: Bonne
A10: Cugy | B10: 30 | C10: Excellente
A11: Denges | B11: 29 | C11: Excellente
A12: Echandens | B12: 30 | C12: Excellente
A13: Ecublens | B13: 35 | C13: Bonne
... A31: Vaulion | B31: 22 | C31: Excellente

Sheet E
A1: Commune | B1: Places de jeux | C1: Terrains de sport / Centres | D1: Total places | G1: Prompt google ia
A2: Assens | B2: 1 | C2: 1 | D2: =B2+C2 -> 2 | G2: Simplement , il me faut : le nombre de place de jeux, place de sport pour chacune de ces communes. Merci d'avance !
A3: Belmont-sur-Lausanne | B3: 2 | C3: 2 | D3: =B3+C3 -> 4
A4: Bourg-en-Lavaux | B4: 3 | C4: 3 | D4: =B4+C4 -> 6
A5: Bremblens | B5: 1 | C5: 1 | D5: =B5+C5 -> 2
A6: Bussigny | B6: 6 | C6: 7 | D6: =B6+C6 -> 13
A7: Chavannes-près-Renens | B7: 5 | C7: 4 | D7: =B7+C7 -> 9
A8: Cheseaux-sur-Lausanne | B8: 4 | C8: 3 | D8: =B8+C8 -> 7
A9: Crissier | B9: 6 | C9: 9 | D9: =B9+C9 -> 15
A10: Cugy | B10: 2 | C10: 2 | D10: =B10+C10 -> 4
A11: Denges | B11: 2 | C11: 2 | D11: =B11+C11 -> 4
A12: Echandens | B12: 2 | C12: 3 | D12: =B12+C12 -> 5
A13: Ecublens | B13: 7 | C13: 11 | D13: =B13+C13 -> 18
A14: Epalinges | B14: 7 | C14: 5 | D14: =B14+C14 -> 12
... A31: Vaulion | B31: 2 | C31: 3 | D31: =B31+C31 -> 5

Sheet F
A1: 2026 | B1: Adopté en | C1: Valable jusqu'en | D1: Impôt rentrée argent | E1: Impôt spécial affecté | F1: Pour-cent total | G1: Immeubles | H1: Constr. non immatric. registre foncier | I1: Impôt personnel fixe | J1: Ventes, cessions, etc. | K1: Ligne directe ascendante | L1: Ligne directe descendante | M1: Ligne collatérale | N1: Entre non-parents | O1: Impôt compl. s/immeubles soc. et fond. | P1: * Chiens | Q1: * Impôt sur les divertissements
D2: 1 | E2: 2 | F2: 1+2 | G2: 0/00 | H2: 0/00 | I2: Fr. | J2: ct. | K2: ct. | L2: ct. | M2: ct. | N2: ct. | O2: ct. | P2: Fr. | Q2: 0/0
A4: DISTRICT D'AIGLE
A5: Aigle | B5: 2021 | C5: 2026 | D5: 66 | E5: - | F5: 66 | G5: 1.2 | H5: 0.5 | I5: - | J5: 50 | K5: 50 | L5: 50 | M5: 100 | N5: 100 | O5: 50 | P5: 100 | Q5: 5
A6: Bex | B6: 2024 | C6: 2026 | D6: 71 | E6: - | F6: 71 | G6: 1.25 | H6: 0.5 | I6: - | J6: 50 | K6: 50 | L6: 50 | M6: 100 | N6: 100 | O6: 50 | P6: 100 | Q6: 0
A7: Chessel | B7: 2025 | C7: 2026 | D7: 65 | E7: - | F7: =+D7 -> 65 | G7: 1 | H7: 0.5 | I7: - | J7: 50 | K7: - | L7: - | M7: 50 | N7: 100 | O7: 50 | P7: 100 | Q7: 0
A8: Corbeyrier | B8: 2025 | C8: 2026 | D8: 74 | E8: - | F8: 74 | G8: 1.5 | H8: 0.5 | I8: - | J8: 50 | K8: 50 | L8: 50 | M8: 100 | N8: 100 | O8: 50 | P8: 100 | Q8: 5
A9: Gryon | B9: 2025 | C9: 2026 | D9: 73.5 | E9: - | F9: 73.5 | G9: 1.5 | H9: 0.5 | I9: - | J9: 50 | K9: - | L9: - | M9: 50 | N9: 100 | O9: 50 | P9: 100 | Q9: 0
A10: Lavey-Morcles | B10: 2025 | C10: 2026 | D10: 71.5 | E10: - | F10: 71.5 | G10: 1.3 | H10: 0.5 | I10: - | J10: 50 | K10: 50 | L10: 50 | M10: 100 | N10: 100 | O10: 50 | P10: 100 | Q10: 75 cts
A11: Leysin | B11: 2025 | C11: 2026 | D11: 78 | E11: - | F11: 78 | G11: 1.5 | H11: 0.5 | I11: - | J11: 50 | K11: 50 | L11: - | M11: 100 | N11: 100 | O11: 50 | P11: 100 | Q11: 15
A12: Noville | B12: 2025 | C12: 2026 | D12: 75 | E12: - | F12: 75 | G12: 1.5 | H12: 0.5 | I12: - | J12: 50 | K12: - | L12: - | M12: 50 | N12: 100 | O12: 50 | P12: 100 | Q12: 0
A13: Ollon | B13: 2025 | C13: 2026 | D13: 68 | E13: - | F13: 68 | G13: 1.3 | H13: 0.5 | I13: - | J13: 50 | K13: - | L13: - | M13: 100 | N13: 100 | O13: 50 | P13: 100 | Q13: 0
A14: Ormont-Dessous | B14: 2024 | C14: 2026 | D14: 74.9 | E14: 2.1 | F14: 77 | G14: 1.5 | H14: 0.5 | I14: - | J14: 50 | K14: 50 | L14: 50 | M14: 100 | N14: 100 | O14: 50 | P14: 100 | Q14: 0
A15: Ormont-Dessus | B15: 2025 | C15: 2026 | D15: 73 | E15: 3 | F15: 76 | G15: 1.5 | H15: 0.5 | I15: - | J15: 50 | K15: 50 | L15: - | M15: 100 | N15: 100 | O15: 50 | P15: 100 | Q15: 0
A16: Rennaz | B16: 2025 | C16: 2027 | D16: 64 | E16: 0 | F16: 64 | G16: 1 | H16: 0.5 | I16: - | J16: 50 | K16: 50 | L16: - | M16: 50 | N16: 100 | O16: 50 | P16: 100 | Q16: 10
A17: Roche | B17: 2025 | C17: 2026 | D17: 66.5 | E17: - | F17: 66.5 | G17: 1.2 | H17: 0.5 | I17: - | J17: 50 | K17: 50 | L17: 50 | M17: 100 | N17: 100 | O17: 50 | P17: 150 | Q17: 0
A18: Villeneuve | B18: 2025 | C18: 2026 | D18: 66.5 | E18: - | F18: 66.5 | G18: 1 | H18: 0.5 | I18: - | J18: 50 | K18: 50 | L18: - | M18: 100 | N18: 100 | O18: 50 | P18: 115 | Q18: 0
A19: Yvorne | B19: 2025 | C19: 2026 | D19: 71.5 | E19: - | F19: 71.5 | G19: 1.5 | H19: 0.5 | I19: - | J19: 50 | K19: 50 | L19: 50 | M19: 100 | N19: 100 | O19: 50 | P19: 100 | Q19: 0
A21: DISTRICT DE LA BROYE-VULLY
A22: Avenches | B22: 2025 | C22: 2026 | D22: 65 | E22: - | F22: 65 | G22: 0.75 | H22: 0.5 | I22: - | J22: 50 | K22: 100 | L22: - | M22: 100 | N22: 100 | O22: 50 | P22: 100 | Q22: 0
